Workbook

Sheet Pivot_Table
A1: 8. Create Pivot Table to analyze total sales by region and product.
A3: Sum of Sales | B3: Column Labels
A4: Row Labels | B4: Books | C4: Clothing | D4: Electronics | E4: Furniture | F4: Office Supplies | G4: Grand Total
A5: Central | B5: 11297.15 | C5: 12200.26 | D5: 6621.24 | E5: 4876.96 | F5: 8472.72 | G5: 43468.33
A6: East | B6: 11389.09 | C6: 2401.45 | D6: 2869.54 | E6: 7592.34 | F6: 8189.22 | G6: 32441.64
A7: North | B7: 8037.01 | C7: 8422.82 | D7: 8191.71 | E7: 6978.08 | F7: 3345.8 | G7: 34975.42
A8: South | B8: 9588.04 | C8: 8393.63 | D8: 11989.07 | E8: 7982.73 | F8: 2295.32 | G8: 40248.79
A9: West | B9: 6691.17 | C9: 10509.43 | D9: 11372.44 | E9: 9182.78 | F9: 6327.76 | G9: 44083.58
A10: Grand Total | B10: 47002.46 | C10: 41927.59 | D10: 41044 | E10: 36612.89 | F10: 28630.82 | G10: 195217.76
G12: Total Sales by Region
G13: Row Labels | H13: Grand Total
G14: Central | H14: 43468.33
G15: East | H15: 32441.64
G16: North | H16: 34975.42
G17: South | H17: 40248.79
G18: West | H18: 44083.58
A29: Month | B29: Total Sales
A30: =DATE(2024,4,1) -> 45383 | B30: =SUMIFS(DATASET!$E$2:$E$201,DATASET!$H$2:$H$201,">="&A30,DATASET!$H$2:$H$201,"<"&EDATE(A30,1)) -> 19029.96
A31: =EDATE(A30,1) -> 45413 | B31: =SUMIFS(DATASET!$E$2:$E$201,DATASET!$H$2:$H$201,">="&A31,DATASET!$H$2:$H$201,"<"&EDATE(A31,1)) -> 18507.34
A32: =EDATE(A31,1) -> 45444 | B32: =SUMIFS(DATASET!$E$2:$E$201,DATASET!$H$2:$H$201,">="&A32,DATASET!$H$2:$H$201,"<"&EDATE(A32,1)) -> 20187.51
A33: =EDATE(A32,1) -> 45474 | B33: =SUMIFS(DATASET!$E$2:$E$201,DATASET!$H$2:$H$201,">="&A33,DATASET!$H$2:$H$201,"<"&EDATE(A33,1)) -> 11609.04
A34: 45505 | B34: =SUMIFS(DATASET!$E$2:$E$201,DATASET!$H$2:$H$201,">="&A34,DATASET!$H$2:$H$201,"<"&EDATE(A34,1)) -> 10091.7
A35: =EDATE(A34,1) -> 45536 | B35: =SUMIFS(DATASET!$E$2:$E$201,DATASET!$H$2:$H$201,">="&A35,DATASET!$H$2:$H$201,"<"&EDATE(A35,1)) -> 20533.5
A36: =EDATE(A35,1) -> 45566 | B36: =SUMIFS(DATASET!$E$2:$E$201,DATASET!$H$2:$H$201,">="&A36,DATASET!$H$2:$H$201,"<"&EDATE(A36,1)) -> 14215.24
A37: =EDATE(A36,1) -> 45597 | B37: =SUMIFS(DATASET!$E$2:$E$201,DATASET!$H$2:$H$201,">="&A37,DATASET!$H$2:$H$201,"<"&EDATE(A37,1)) -> 20135.03
A38: =EDATE(A37,1) -> 45627 | B38: =SUMIFS(DATASET!$E$2:$E$201,DATASET!$H$2:$H$201,">="&A38,DATASET!$H$2:$H$201,"<"&EDATE(A38,1)) -> 11120.04
A39: =EDATE(A38,1) -> 45658 | B39: =SUMIFS(DATASET!$E$2:$E$201,DATASET!$H$2:$H$201,">="&A39,DATASET!$H$2:$H$201,"<"&EDATE(A39,1)) -> 14914.65
A40: =EDATE(A39,1) -> 45689 | B40: =SUMIFS(DATASET!$E$2:$E$201,DATASET!$H$2:$H$201,">="&A40,DATASET!$H$2:$H$201,"<"&EDATE(A40,1)) -> 14006.36
A41: =EDATE(A40,1) -> 45717 | B41: =SUMIFS(DATASET!$E$2:$E$201,DATASET!$H$2:$H$201,">="&A41,DATASET!$H$2:$H$201,"<"&EDATE(A41,1)) -> 17655.22
A42: =EDATE(A41,1) -> 45748 | B42: =SUMIFS(DATASET!$E$2:$E$201,DATASET!$H$2:$H$201,">="&A42,DATASET!$H$2:$H$201,"<"&EDATE(A42,1)) -> 3212.17
A46: Product | B46: Total Sales
A47: Books | B47: =B10 -> 47002.46
A48: Clothing | B48: =C10 -> 41927.59
A49: Electronics | B49: =D10 -> 41044
A50: Furniture | B50: =E10 -> 36612.89
A51: Office Supplies | B51: =F10 -> 28630.82

Sheet DATASET
A1: Customer_ID | B1: Customer_Name | C1: Region | D1: Product_Category | E1: Sales | F1: Quantity | G1: Discount | H1: Order_Date | I1: Profit
A2: CUST019 | B2: James Davis | C2: West | D2: Books | E2: 1036.09 | F2: 4 | G2: 0.2 | H2: 45392 | I2: 331.55
A3: CUST012 | B3: Robert Anderson | C3: West | D3: Clothing | E3: 1101.28 | F3: 3 | G3: 0.2 | H3: 45393 | I3: 440.51
A4: CUST017 | B4: James Taylor | C4: East | D4: Books | E4: 713.34 | F4: 17 | G4: 0 | H4: 45396 | I4: 285.34
A5: CUST005 | B5: Robert Anderson | C5: South | D5: Electronics | E5: 760.93 | F5: 4 | G5: 0.15 | H5: 45396 | I5: 161.7
A6: CUST030 | B6: James Wilson | C6: North | D6: Books | E6: 847 | F6: 12 | G6: 0.2 | H6: 45397 | I6: 271.04
A7: CUST007 | B7: Michael Anderson | C7: North | D7: Furniture | E7: 965.64 | F7: 8 | G7: 0.1 | H7: 45398 | I7: 304.18
A8: CUST001 | B8: Linda Wilson | C8: West | D8: Electronics | E8: 1317.53 | F8: 12 | G8: 0.05 | H8: 45398 | I8: 312.91
A9: CUST026 | B9: Mary Davis | C9: East | D9: Furniture | E9: 1074.47 | F9: 6 | G9: 0.2 | H9: 45401 | I9: 300.85
A10: CUST009 | B10: Linda Jackson | C10: Central | D10: Books | E10: 501.54 | F10: 11 | G10: 0.05 | H10: 45401 | I10: 190.59
A11: CUST010 | B11: David Thomas | C11: Central | D11: Clothing | E11: 737.31 | F11: 2 | G11: 0.05 | H11: 45401 | I11: 350.22
A12: CUST014 | B12: Emma Davis | C12: West | D12: Office Supplies | E12: 1572.82 | F12: 6 | G12: 0.05 | H12: 45402 | I12: 672.38
A13: CUST014 | B13: David Thomas | C13: Central | D13: Books | E13: 1343.13 | F13: 14 | G13: 0.15 | H13: 45404 | I13: 456.66
... A201: CUST016 | B201: David Thomas | C201: South | D201: Clothing | E201: 928.32 | F201: 2 | G201: 0.05 | H201: 45754 | I201: 440.95

Sheet Main_Task
A1: Main Task to Perform :- | K1: Sales | L1: Quantity | M1: Discount | N1: Profit | P1: Sales | Q1: Profit
K2: 1036.09 | L2: 4 | M2: 0.2 | N2: 331.55 | P2: 1036.09 | Q2: 331.55
A3: 1. Apply conditional formatting to highlight top 10 customers based on total purchase. | K3: 1101.28 | L3: 3 | M3: 0.2 | N3: 440.51 | P3: 1101.28 | Q3: 440.51
K4: 713.34 | L4: 17 | M4: 0 | N4: 285.34 | P4: 713.34 | Q4: 285.34
A5: Customer ID | B5: Total Purchase | K5: 760.93 | L5: 4 | M5: 0.15 | N5: 161.7 | P5: 760.93 | Q5: 161.7
A6: {=_xlfn._xlws.SORT(_xlfn.UNIQUE(SalesData[Customer_ID]))} -> CUST001 | B6: =SUMIF(SalesData[Customer_ID],A6,SalesData[Sales]) -> 6549.55 | K6: 847 | L6: 12 | M6: 0.2 | N6: 271.04 | P6: 847 | Q6: 271.04
A7: CUST002 | B7: =SUMIF(SalesData[Customer_ID],A7,SalesData[Sales]) -> 6481.43 | K7: 965.64 | L7: 8 | M7: 0.1 | N7: 304.18 | P7: 965.64 | Q7: 304.18
A8: CUST003 | B8: =SUMIF(SalesData[Customer_ID],A8,SalesData[Sales]) -> 8490.18 | K8: 1317.53 | L8: 12 | M8: 0.05 | N8: 312.91 | P8: 1317.53 | Q8: 312.91
A9: CUST004 | B9: =SUMIF(SalesData[Customer_ID],A9,SalesData[Sales]) -> 7813.59 | K9: 1074.47 | L9: 6 | M9: 0.2 | N9: 300.85 | P9: 1074.47 | Q9: 300.85
A10: CUST005 | B10: =SUMIF(SalesData[Customer_ID],A10,SalesData[Sales]) -> 6666.13 | K10: 501.54 | L10: 11 | M10: 0.05 | N10: 190.59 | P10: 501.54 | Q10: 190.59
A11: CUST006 | B11: =SUMIF(SalesData[Customer_ID],A11,SalesData[Sales]) -> 2699.75 | K11: 737.31 | L11: 2 | M11: 0.05 | N11: 350.22 | P11: 737.31 | Q11: 350.22
A12: CUST007 | B12: =SUMIF(SalesData[Customer_ID],A12,SalesData[Sales]) -> 9941.88 | K12: 1572.82 | L12: 6 | M12: 0.05 | N12: 672.38 | P12: 1572.82 | Q12: 672.38
A13: CUST008 | B13: =SUMIF(SalesData[Customer_ID],A13,SalesData[Sales]) -> 9760.8 | K13: 1343.13 | L13: 14 | M13: 0.15 | N13: 456.66 | P13: 1343.13 | Q13: 456.66
A14: CUST009 | B14: =SUMIF(SalesData[Customer_ID],A14,SalesData[Sales]) -> 6505.2 | K14: 1191.58 | L14: 14 | M14: 0.05 | N14: 452.8 | P14: 1191.58 | Q14: 452.8
A15: CUST010 | B15: =SUMIF(SalesData[Customer_ID],A15,SalesData[Sales]) -> 4259.22 | K15: 822.28 | L15: 7 | M15: 0.05 | N15: 273.41 | P15: 822.28 | Q15: 273.41
A16: CUST011 | B16: =SUMIF(SalesData[Customer_ID],A16,SalesData[Sales]) -> 3762.29 | K16: 521.67 | L16: 15 | M16: 0.15 | N16: 155.2 | P16: 521.67 | Q16: 155.2
A17: CUST012 | B17: =SUMIF(SalesData[Customer_ID],A17,SalesData[Sales]) -> 8339 | K17: 1502.93 | L17: 14 | M17: 0.2 | N17: 300.59 | P17: 1502.93 | Q17: 300.59
A18: CUST013 | B18: =SUMIF(SalesData[Customer_ID],A18,SalesData[Sales]) -> 4162.44 | K18: 877.58 | L18: 10 | M18: 0.15 | N18: 298.38 | P18: 877.58 | Q18: 298.38
... A35: CUST030 | B35: =SUMIF(SalesData[Customer_ID],A35,SalesData[Sales]) -> 7928.71 | K35: 967.89 | L35: 10 | M35: 0.1 | N35: 217.78 | P35: 967.89 | Q35: 217.78
K36: 1200.9 | L36: 14 | M36: 0.05 | N36: 513.38 | P36: 1200.9 | Q36: 513.38
A37: 2. Perform WHAT IF Analysis to see impact of changing discount on total profit. | K37: 472.38 | L37: 12 | M37: 0.2 | N37: 151.16 | P37: 472.38 | Q37: 151.16
K38: 840.92 | L38: 9 | M38: 0.05 | N38: 359.49 | P38: 840.92 | Q38: 359.49
A39: Discount | B39: =E40 -> 68037.992 | D39: Discount Input | E39: 0.1 | K39: 1410.06 | L39: 11 | M39: 0.05 | N39: 468.84 | P39: 1410.06 | Q39: 468.84
A40: 0 | B40: 87559.768 | D40: Total Profit | E40: {=SUMPRODUCT(DATASET!$I$2:$I$201+DATASET!$E$2:$E$201*DATASET!$G$2:$G$201)-SUM(DATASET!$E$2:$E$201)*E39} -> 68037.992 | K40: 773.09 | L40: 13 | M40: 0.15 | N40: 229.99 | P40: 773.09 | Q40: 229.99
A41: 0.05 | B41: 77798.88 | K41: 580.43 | L41: 19 | M41: 0.15 | N41: 197.35 | P41: 580.43 | Q41: 197.35
A42: 0.1 | B42: 68037.992 | K42: 1151.21 | L42: 15 | M42: 0.1 | N42: 414.44 | P42: 1151.21 | Q42: 414.44
A43: 0.15 | B43: 58277.104 | K43: 1025.98 | L43: 5 | M43: 0.2 | N43: 369.35 | P43: 1025.98 | Q43: 369.35
A44: 0.2 | B44: 48516.216 | K44: 556.42 | L44: 11 | M44: 0.15 | N44: 212.83 | P44: 556.42 | Q44: 212.83
K45: 840.85 | L45: 19 | M45: 0.1 | N45: 302.71 | P45: 840.85 | Q45: 302.71
A46: 4. Use 'Descriptive Statistics' from Analysis Toolpak on the dataset. | K46: 1227.25 | L46: 12 | M46: 0.15 | N46: 365.11 | P46: 1227.25 | Q46: 365.11
K47: 856.7 | L47: 2 | M47: 0 | N47: 214.18 | P47: 856.7 | Q47: 214.18
A48: Sales | C48: Quantity | E48: Discount | G48: Profit | K48: 1225.42 | L48: 8 | M48: 0.15 | N48: 468.72 | P48: 1225.42 | Q48: 468.72
K49: 1001.57 | L49: 12 | M49: 0 | N49: 450.71 | P49: 1001.57 | Q49: 450.71
A50: Mean | B50: 976.0888 | C50: Mean | D50: 9.995 | E50: Mean | F50: 0.09725 | G50: Mean | H50: 341.43505 | K50: 1186.85 | L50: 19 | M50: 0.2 | N50: 332.32 | P50: 1186.85 | Q50: 332.32
A51: Standard Error | B51: 21.16185 | C51: Standard Error | D51: 0.39927683 | E51: Standard Error | F51: 0.0051142414 | G51: Standard Error | H51: 9.6001196 | K51: 775.45 | L51: 6 | M51: 0.1 | N51: 174.48 | P51: 775.45 | Q51: 174.48
A52: Median | B52: 976.72 | C52: Median | D52: 10 | E52: Median | F52: 0.1 | G52: Median | H52: 332.255 | K52: 1021.47 | L52: 6 | M52: 0.05 | N52: 242.6 | P52: 1021.47 | Q52: 242.6
A53: Mode | B53: #N/A | C53: Mode | D53: 8 | E53: Mode | F53: 0.2 | G53: Mode | H53: #N/A | K53: 1226.62 | L53: 7 | M53: 0.1 | N53: 551.98 | P53: 1226.62 | Q53: 551.98
A54: Standard Deviation | B54: 299.27376 | C54: Standard Deviation | D54: 5.646627 | E54: Standard Deviation | F54: 0.072326295 | G54: Standard Deviation | H54: 135.76619 | K54: 1086.93 | L54: 2 | M54: 0 | N54: 380.43 | P54: 1086.93 | Q54: 380.43
A55: Sample Variance | B55: 89564.783 | C55: Sample Variance | D55: 31.884397 | E55: Sample Variance | F55: 0.005231093 | G55: Sample Variance | H55: 18432.459 | K55: 942.9 | L55: 18 | M55: 0.1 | N55: 339.44 | P55: 942.9 | Q55: 339.44
A56: Kurtosis | B56: -0.088595232 | C56: Kurtosis | D56: -1.2091054 | E56: Kurtosis | F56: -1.3257012 | G56: Kurtosis | H56: 0.26450644 | K56: 818.8 | L56: 15 | M56: 0.15 | N56: 173.99 | P56: 818.8 | Q56: 173.99
...

Sheet Dashboard
A1: Sales & Profit Dashboard
A3: Total Sales | B3: =SUM(SalesData[Sales]) -> 195217.76 | E3: Select Region | F3: Central
A4: Total Profit | B4: =SUM(SalesData[Profit]) -> 68287.01
A5: Total Quantity | B5: =SUM(SalesData[Quantity]) -> 1999
A6: Average Discount | B6: =AVERAGE(SalesData[Discount]) -> 0.09725 | F6: ="Total Sales by Region - "&F3 -> Total Sales by Region - Central
A42: Key Insights:
A43: 1. West reigon has the highest total sales.
A44: 2. Books is the highest-selling product category.
A45: 3. East region has the lowest total sales.
A46: 4. Office Supplies has the lowest total sales among product categories.
