Workbook
Name NativeTimeline_Date: #N/A
Name Slicer_Region: #N/A

Sheet DataSet
A1: Transaction_ID | B1: Date | C1: Customer_ID | D1: Customer_Name | E1: Product_ID | F1: Product_Name | G1: Category | H1: Quantity | I1: Unit_Price | J1: Payment_Method | K1: Region | L1: Customer_Segment | M1: Customer_Since | N1: Total_Amount
A2: TRX0155 | B2: 45393 | C2: CUST023 | D2: Paul Baker | E2: P009 | F2: Monitor | G2: Electronics | H2: 3 | I2: 249.99 | J2: Cash | K2: Central | L2: Basic | M2: 44425 | N2: 749.97
A3: TRX0023 | B3: 45396 | C3: CUST013 | D3: Joseph Jackson | E3: P009 | F3: Monitor | G3: Electronics | H3: 3 | I3: 249.99 | J3: Credit Card | K3: Central | L3: Premium | M3: 44575 | N3: 749.97
A4: TRX0139 | B4: 45399 | C4: CUST021 | D4: Kevin Scott | E4: P005 | F4: Blender | G4: Appliances | H4: 3 | I4: 59.99 | J4: PayPal | K4: South | L4: Standard | M4: 45262 | N4: 179.97
A5: TRX0043 | B5: 45400 | C5: CUST046 | D5: Kathleen Bennett | E5: P005 | F5: Blender | G5: Appliances | H5: 3 | I5: 59.99 | J5: Cash | K5: North | L5: Premium | M5: 45114 | N5: 179.97
A6: TRX0212 | B6: 45400 | C6: CUST003 | D6: Michael Brown | E6: P008 | F6: Bookshelf | G6: Furniture | H6: 5 | I6: 149.99 | J6: Credit Card | K6: North | L6: Premium | M6: 45295 | N6: 749.95
A7: TRX0092 | B7: 45403 | C7: CUST024 | D7: Dorothy Nelson | E7: P005 | F7: Blender | G7: Appliances | H7: 2 | I7: 59.99 | J7: Cash | K7: West | L7: Standard | M7: 44746 | N7: 119.98
A8: TRX0193 | B8: 45403 | C8: CUST024 | D8: Dorothy Nelson | E8: P003 | F8: Headphones | G8: Electronics | H8: 5 | I8: 149.99 | J8: Credit Card | K8: Central | L8: Standard | M8: 44418 | N8: 749.95
A9: TRX0240 | B9: 45403 | C9: CUST017 | D9: Charles Allen | E9: P005 | F9: Blender | G9: Appliances | H9: 3 | I9: 59.99 | J9: Debit Card | K9: South | L9: Basic | M9: 45007 | N9: 179.97
A10: TRX0135 | B10: 45405 | C10: CUST009 | D10: Robert Thomas | E10: P001 | F10: Laptop | G10: Electronics | H10: 3 | I10: 899.99 | J10: PayPal | K10: East | L10: Standard | M10: 45299 | N10: 2699.97
A11: TRX0185 | B11: 45408 | C11: CUST026 | D11: Karen Hill | E11: P005 | F11: Blender | G11: Appliances | H11: 3 | I11: 59.99 | J11: Cash | K11: West | L11: Premium | M11: 45207 | N11: 179.97
A12: TRX0138 | B12: 45408 | C12: CUST022 | D12: Susan Green | E12: P008 | F12: Bookshelf | G12: Furniture | H12: 1 | I12: 149.99 | J12: Credit Card | K12: West | L12: Standard | M12: 45103 | N12: 149.99
A13: TRX0209 | B13: 45408 | C13: CUST046 | D13: Kathleen Bennett | E13: P008 | F13: Bookshelf | G13: Furniture | H13: 5 | I13: 149.99 | J13: Debit Card | K13: North | L13: Basic | M13: 44830 | N13: 749.95
... A251: TRX0064 | B251: 45758 | C251: CUST031 | D251: Steven Turner | E251: P010 | F251: Keyboard | G251: Electronics | H251: 3 | I251: 89.99 | J251: Debit Card | K251: North | L251: Premium | M251: 44878 | N251: 269.97

Sheet Scenario Summary
B2: Scenario Summary
D3: Current Values: | E3: Low Sales | F3: Normal Sales | G3: High Sales
E4: Created by Sneha on 19-09-2026 | F4: Created by Sneha on 19-09-2026 | G4: Created by Sneha on 19-09-2026
B5: Changing Cells:
C6: $B$408 | D6: 10 | E6: 5 | F6: 10 | G6: 20
C7: $B$409 | D7: 100 | E7: 80 | F7: 100 | G7: 150
B8: Result Cells:
C9: $B$410 | D9: 1000 | E9: 400 | F9: 1000 | G9: 3000
B10: Notes: Current Values column represents values of changing cells at
B11: time Scenario Summary Report was created. Changing cells for each
B12: scenario are highlighted in gray.

Sheet Main Task
A1: Task 1: Date & Time Functions.
A3: Function | B3: Result
A4: TODAY | B4: =TODAY() -> 46286
A5: NOW | B5: =NOW() -> 46286.527
A6: DATEDIFF | B6: =DATEDIF(DataSet!M2,DataSet!B2,"d") -> 968
A7: EOMONTH | B7: =EOMONTH(DataSet!B2,0) -> 45412
A9: Task 2: FILTER Function.
A11: Electronics Transactions
A12: {=_xlfn._xlws.FILTER(DataSet!A2:N251,DataSet!G2:G251="Electronics","No records found")} -> TRX0155 | B12: 45393 | C12: CUST023 | D12: Paul Baker | E12: P009 | F12: Monitor | G12: Electronics | H12: 3 | I12: 249.99 | J12: Cash | K12: Central | L12: Basic | M12: 44425 | N12: 749.97
A13: TRX0023 | B13: 45396 | C13: CUST013 | D13: Joseph Jackson | E13: P009 | F13: Monitor | G13: Electronics | H13: 3 | I13: 249.99 | J13: Credit Card | K13: Central | L13: Premium | M13: 44575 | N13: 749.97
A14: TRX0193 | B14: 45403 | C14: CUST024 | D14: Dorothy Nelson | E14: P003 | F14: Headphones | G14: Electronics | H14: 5 | I14: 149.99 | J14: Credit Card | K14: Central | L14: Standard | M14: 44418 | N14: 749.95
A15: TRX0135 | B15: 45405 | C15: CUST009 | D15: Robert Thomas | E15: P001 | F15: Laptop | G15: Electronics | H15: 3 | I15: 899.99 | J15: PayPal | K15: East | L15: Standard | M15: 45299 | N15: 2699.97
A16: TRX0191 | B16: 45409 | C16: CUST038 | D16: Michelle Rogers | E16: P002 | F16: Smartphone | G16: Electronics | H16: 3 | I16: 699.99 | J16: Credit Card | K16: West | L16: Basic | M16: 44577 | N16: 2099.97
A17: TRX0230 | B17: 45409 | C17: CUST027 | D17: George Adams | E17: P001 | F17: Laptop | G17: Electronics | H17: 1 | I17: 899.99 | J17: Debit Card | K17: North | L17: Standard | M17: 44920 | N17: 899.99
A18: TRX0134 | B18: 45410 | C18: CUST010 | D18: Maria Garcia | E18: P002 | F18: Smartphone | G18: Electronics | H18: 2 | I18: 699.99 | J18: Cash | K18: North | L18: Basic | M18: 44781 | N18: 1399.98
A19: TRX0122 | B19: 45410 | C19: CUST025 | D19: Mark Carter | E19: P001 | F19: Laptop | G19: Electronics | H19: 4 | I19: 899.99 | J19: Credit Card | K19: West | L19: Standard | M19: 45327 | N19: 3599.96
A20: TRX0222 | B20: 45410 | C20: CUST048 | D20: Virginia Sanders | E20: P009 | F20: Monitor | G20: Electronics | H20: 3 | I20: 249.99 | J20: Credit Card | K20: North | L20: Premium | M20: 45224 | N20: 749.97
A21: TRX0231 | B21: 45412 | C21: CUST018 | D21: Barbara Young | E21: P002 | F21: Smartphone | G21: Electronics | H21: 5 | I21: 699.99 | J21: Cash | K21: West | L21: Basic | M21: 45167 | N21: 3499.95
A22: TRX0239 | B22: 45413 | C22: CUST012 | D22: Patricia Moore | E22: P002 | F22: Smartphone | G22: Electronics | H22: 4 | I22: 699.99 | J22: Cash | K22: East | L22: Standard | M22: 44409 | N22: 2799.96
A23: TRX0204 | B23: 45415 | C23: CUST044 | D23: Cynthia Price | E23: P009 | F23: Monitor | G23: Electronics | H23: 4 | I23: 249.99 | J23: PayPal | K23: North | L23: Standard | M23: 44468 | N23: 999.96
A24: TRX0071 | B24: 45422 | C24: CUST036 | D24: Nancy Collins | E24: P009 | F24: Monitor | G24: Electronics | H24: 5 | I24: 249.99 | J24: Credit Card | K24: West | L24: Standard | M24: 44525 | N24: 1249.95
... A142: TRX0064 | B142: 45758 | C142: CUST031 | D142: Steven Turner | E142: P010 | F142: Keyboard | G142: Electronics | H142: 3 | I142: 89.99 | J142: Debit Card | K142: North | L142: Premium | M142: 44878 | N142: 269.97
A144: Task 3: Conditional Formatting with Icons/Arrows.
A146: Transaction_ID | B146: Customer_Name | C146: Product_Name | D146: Total_Amount
A147: =DataSet!A2 -> TRX0155 | B147: =DataSet!D2 -> Paul Baker | C147: =DataSet!F2 -> Monitor | D147: =DataSet!N2 -> 749.97
A148: =DataSet!A3 -> TRX0023 | B148: =DataSet!D3 -> Joseph Jackson | C148: =DataSet!F3 -> Monitor | D148: =DataSet!N3 -> 749.97
A149: =DataSet!A4 -> TRX0139 | B149: =DataSet!D4 -> Kevin Scott | C149: =DataSet!F4 -> Blender | D149: =DataSet!N4 -> 179.97
A150: =DataSet!A5 -> TRX0043 | B150: =DataSet!D5 -> Kathleen Bennett | C150: =DataSet!F5 -> Blender | D150: =DataSet!N5 -> 179.97
A151: =DataSet!A6 -> TRX0212 | B151: =DataSet!D6 -> Michael Brown | C151: =DataSet!F6 -> Bookshelf | D151: =DataSet!N6 -> 749.95
A152: =DataSet!A7 -> TRX0092 | B152: =DataSet!D7 -> Dorothy Nelson | C152: =DataSet!F7 -> Blender | D152: =DataSet!N7 -> 119.98
A153: =DataSet!A8 -> TRX0193 | B153: =DataSet!D8 -> Dorothy Nelson | C153: =DataSet!F8 -> Headphones | D153: =DataSet!N8 -> 749.95
A154: =DataSet!A9 -> TRX0240 | B154: =DataSet!D9 -> Charles Allen | C154: =DataSet!F9 -> Blender | D154: =DataSet!N9 -> 179.97
A155: =DataSet!A10 -> TRX0135 | B155: =DataSet!D10 -> Robert Thomas | C155: =DataSet!F10 -> Laptop | D155: =DataSet!N10 -> 2699.97
A156: =DataSet!A11 -> TRX0185 | B156: =DataSet!D11 -> Karen Hill | C156: =DataSet!F11 -> Blender | D156: =DataSet!N11 -> 179.97
A157: =DataSet!A12 -> TRX0138 | B157: =DataSet!D12 -> Susan Green | C157: =DataSet!F12 -> Bookshelf | D157: =DataSet!N12 -> 149.99
A158: =DataSet!A13 -> TRX0209 | B158: =DataSet!D13 -> Kathleen Bennett | C158: =DataSet!F13 -> Bookshelf | D158: =DataSet!N13 -> 749.95
... A396: =DataSet!A251 -> TRX0064 | B396: =DataSet!D251 -> Steven Turner | C396: =DataSet!F251 -> Keyboard | D396: =DataSet!N251 -> 269.97
A400: Task 4: Create Timestamp.
A402: Current Timestamp | B402: =NOW() -> 46286.527
A405: Task 5 & 6: WHAT-IF Analysis – Scenario Manager & Goal Seek
...

Sheet Pivot tables
A1: Task 12.1: Total Revenue by Region
A3: Row Labels | B3: Sum of Total_Amount
A4: Central | B4: 41288.34
A5: East | B5: 59288.39
A6: North | B6: 50808.31
A7: South | B7: 36398.75
A8: West | B8: 41408.68
A9: Grand Total | B9: 229192.47
A12: Task 12.2: Total Revenue and Quantity by Category
A14: Row Labels | B14: Sum of Total_Amount | C14: Sum of Quantity
A15: Appliances | B15: 8338.74 | C15: 126
A16: Electronics | B16: 171756.05 | C16: 395
A17: Furniture | B17: 49097.68 | C17: 232
A18: Grand Total | B18: 229192.47 | C18: 753
A20: Task 12.3: Revenue by Customer Segment and Payment Method
A22: Sum of Total_Amount | B22: Column Labels
A23: Row Labels | B23: Cash | C23: Credit Card | D23: Debit Card | E23: PayPal | F23: Grand Total
A24: Basic | B24: 15199.44 | C24: 16009.36 | D24: 9839.57 | E24: 21129.44 | F24: 62177.81
A25: Premium | B25: 20949.03 | C25: 24309.23 | D25: 18429.46 | E25: 20969.4 | F25: 84657.12
A26: Standard | B26: 21279.32 | C26: 21129.37 | D26: 23849.28 | E26: 16099.57 | F26: 82357.54
A27: Grand Total | B27: 57427.79 | C27: 61447.96 | D27: 52118.31 | E27: 58198.41 | F27: 229192.47
A29: Task 12.4: Product Sales and Quantity Analysis
A31: Row Labels | B31: Sum of Quantity | C31: Sum of Total_Amount
A32: Blender | B32: 87 | C32: 5219.13
A33: Bookshelf | B33: 102 | C33: 15298.98
A34: Coffee Maker | B34: 39 | C34: 3119.61
A35: Desk | B35: 78 | C35: 23399.22
A36: Headphones | B36: 47 | C36: 7049.53
A37: Keyboard | B37: 89 | C37: 8009.11
A38: Laptop | B38: 75 | C38: 67499.25
A39: Monitor | B39: 88 | C39: 21999.12
A40: Office Chair | B40: 52 | C40: 10399.48
A41: Smartphone | B41: 96 | C41: 67199.04
A42: Grand Total | B42: 753 | C42: 229192.47

Sheet Dashboard
A1: Data Intelligence
A3: Total Revenue | D3: Total Transactions | G3: Total Quantity | J3: Average Transaction value
A4: =SUM(DataSet!N2:N251) -> 229192.47 | D4: =COUNTA(DataSet!A2:A251) -> 250 | G4: =SUM(DataSet!H2:H251) -> 753 | J4: =AVERAGE(DataSet!N2:N251) -> 916.76988
A26: Key Insights & storytelling
A28: Insight | B28: Result
A29: Total revenue | B29: =SUM(DataSet!N2:N251) -> 229192.47
A30: Total Transactions | B30: =COUNTA(DataSet!A2:A251) -> 250
A31: Total Quantity sold | B31: =SUM(DataSet!H2:H251) -> 753
A32: Average Transaction value | B32: =AVERAGE(DataSet!N2:N251) -> 916.76988
A33: Top Customer | B33: ='Main Task'!E449 -> Mark Carter
A34: Most Sold Product | B34: ='Main Task'!E456 -> Bookshelf
A37: Highest Revenue Region | B37: =INDEX('Main Task'!D463:D467,MATCH(MAX('Main Task'!E463:E467),'Main Task'!E463:E467,0)) -> East
A38: High-Value Customer Count | B38: =COUNTIF(_xlfn.ANCHORARRAY('Main Task'!F473),"High-Value") -> 24
A39: Most Frequently Purchased Product | B39: =INDEX('Main Task'!D528:D537,MATCH("Most Frequent",'Main Task'!F528:F537,0)) -> Bookshelf
A41: Business Summary
A43: The dashboard summarizes customer transactions using revenue, quantity, customer, product and regional analysis. It highlights key performance indicators,
A44: identifies the top customer and most frequently purchased products, and provides regional and category-level revenue insights for easier business analysis.
