Workbook
Name NativeTimeline_Order_Date: #N/A
Name Slicer_Product_Category: #N/A
Name Slicer_Region: #N/A

Sheet Pivot Tables
A1: Task 3: Create Pivot Tables – Analyze and summarize the dataset using Pivot Tables.
A3: Row Labels | B3: Sum of Sales
A4: Central | B4: 3678973.1
A5: East | B5: 3891741.7
A6: North | B6: 3866226.5
A7: South | B7: 3919562.1
A8: West | B8: 4097279.9
A9: (blank)
A10: Grand Total | B10: 19453783
A12: Pivot Table 2: Summarize Total sales and Total Profit by Product Category.
A14: Row Labels | B14: Sum of Sales | C14: Sum of Profit
A15: Books | B15: 4097279.9 | C15: 726304.07
A16: Clothing | B16: 3919562.1 | C16: 746508.07
A17: Electronics | B17: 3866226.5 | C17: 769795.44
A18: Furniture | B18: 3891741.7 | C18: 729963.8
A19: Office Supplies | B19: 3678973.1 | C19: 682854.52
A20: (blank)
A21: Grand Total | B21: 19453783 | C21: 3655425.9
A23: Pivot Table 3: Summarize Total Quantity Sold by Salesperson.
A25: Row Labels | B25: Sum of Quantity
A26: Amit | B26: 153
A27: Karan | B27: 163
A28: Meera | B28: 180
A29: Neha | B29: 173
A30: Pooja | B30: 179
A31: Rahul | B31: 165
A32: Riya | B32: 179
A33: Vikram | B33: 173
A34: (blank)
A35: Grand Total | B35: 1365
A37: Pivot Tables 4: Summarize Total Sales by Customer Segment and Payment Mode.
A39: Sum of Sales | B39: Column Labels
A40: Row Labels | B40: Cash | C40: Credit Card | D40: Debit Card | E40: Net Banking | F40: UPI | G40: (blank) | H40: Grand Total
A41: Corporate | B41: 1069799.4 | C41: 1131819.7 | D41: 957146.32 | E41: 835604.04 | F41: 893309.1 | H41: 4887678.6
A42: Education | B42: 1237138.5 | C42: 839850.2 | D42: 1052593.5 | E42: 863411.1 | F42: 1010783 | H42: 5003776.3
A43: Retail | B43: 1020549.6 | C43: 1002873.2 | D43: 1026966 | E43: 969490.4 | F43: 974188 | H43: 4994067.2
A44: Small Business | B44: 769792.44 | C44: 945019 | D44: 855035.88 | E44: 1010467.5 | F44: 987946.4 | H44: 4568261.2
A45: (blank)
A46: Grand Total | B46: 4097279.9 | C46: 3919562.1 | D46: 3891741.7 | E46: 3678973.1 | F46: 3866226.5 | H46: 19453783

Sheet DataSet
A1: Customer_ID | B1: Customer_Name | C1: Region | D1: Product_Category | E1: Unit_Price | F1: Quantity | G1: Discount | H1: Order_Date | I1: Sales | J1: Profit | K1: Salesperson | L1: Payment_Mode | M1: Customer_Segment
A2: ="CUST"&TEXT(ROW()-1,"0000") -> CUST0001 | B2: {=INDEX({"Aarav","Vivaan","Aditya","Arjun","Kabir","Rohan","Ananya","Diya","Ishita","Meera","Riya","Pooja","Neha","Kavya","Aisha","Priya","Rahul","Karan","Vikram","Sahil"},MOD(ROW()-2,20)+1)&" "&INDEX({"Shah","Patel","Mehta","Desai","Joshi","Gupta","Verma","Sharma","Trivedi","Rana","Mishra","Kapoor","Iyer","Nair","Singh"},MOD(INT((ROW()-2)/20),15)+1)} -> Aarav Shah | C2: {=INDEX({"North","South","East","West","Central"},MOD(ROW()-2,5)+1)} -> North | D2: {=INDEX({"Electronics","Clothing","Furniture","Books","Office Supplies"},MOD(ROW()-2,5)+1)} -> Electronics | E2: =ROUND(500+MOD((ROW()-2)*137,44500),2) -> 500 | F2: =MOD((ROW()-2)*7,11)+1 -> 1 | G2: =CHOOSE(MOD(ROW()-2,8)+1,0,0.02,0.05,0.08,0.1,0.12,0.15,0.2) -> 0 | H2: =DATE(2025,1,1)+MOD(ROW()-2,365) -> 45658 | I2: =ROUND(E2*F2*(1-G2),2) -> 500 | J2: =ROUND(I2*(0.08+MOD(ROW()-2,12)*0.02),2) -> 40 | K2: {=INDEX({"Amit","Neha","Riya","Karan","Pooja","Rahul","Meera","Vikram"},MOD(ROW()-2,8)+1)} -> Amit | L2: {=INDEX({"UPI","Credit Card","Debit Card","Cash","Net Banking"},MOD(ROW()-2,5)+1)} -> UPI | M2: {=INDEX({"Retail","Corporate","Education","Small Business"},MOD(ROW()-2,4)+1)} -> Retail
A3: ="CUST"&TEXT(ROW()-1,"0000") -> CUST0002 | B3: {=INDEX({"Aarav","Vivaan","Aditya","Arjun","Kabir","Rohan","Ananya","Diya","Ishita","Meera","Riya","Pooja","Neha","Kavya","Aisha","Priya","Rahul","Karan","Vikram","Sahil"},MOD(ROW()-2,20)+1)&" "&INDEX({"Shah","Patel","Mehta","Desai","Joshi","Gupta","Verma","Sharma","Trivedi","Rana","Mishra","Kapoor","Iyer","Nair","Singh"},MOD(INT((ROW()-2)/20),15)+1)} -> Vivaan Shah | C3: {=INDEX({"North","South","East","West","Central"},MOD(ROW()-2,5)+1)} -> South | D3: {=INDEX({"Electronics","Clothing","Furniture","Books","Office Supplies"},MOD(ROW()-2,5)+1)} -> Clothing | E3: =ROUND(500+MOD((ROW()-2)*137,44500),2) -> 637 | F3: =MOD((ROW()-2)*7,11)+1 -> 8 | G3: =CHOOSE(MOD(ROW()-2,8)+1,0,0.02,0.05,0.08,0.1,0.12,0.15,0.2) -> 0.02 | H3: =DATE(2025,1,1)+MOD(ROW()-2,365) -> 45659 | I3: =ROUND(E3*F3*(1-G3),2) -> 4994.08 | J3: =ROUND(I3*(0.08+MOD(ROW()-2,12)*0.02),2) -> 499.41 | K3: {=INDEX({"Amit","Neha","Riya","Karan","Pooja","Rahul","Meera","Vikram"},MOD(ROW()-2,8)+1)} -> Neha | L3: {=INDEX({"UPI","Credit Card","Debit Card","Cash","Net Banking"},MOD(ROW()-2,5)+1)} -> Credit Card | M3: {=INDEX({"Retail","Corporate","Education","Small Business"},MOD(ROW()-2,4)+1)} -> Corporate
A4: ="CUST"&TEXT(ROW()-1,"0000") -> CUST0003 | B4: {=INDEX({"Aarav","Vivaan","Aditya","Arjun","Kabir","Rohan","Ananya","Diya","Ishita","Meera","Riya","Pooja","Neha","Kavya","Aisha","Priya","Rahul","Karan","Vikram","Sahil"},MOD(ROW()-2,20)+1)&" "&INDEX({"Shah","Patel","Mehta","Desai","Joshi","Gupta","Verma","Sharma","Trivedi","Rana","Mishra","Kapoor","Iyer","Nair","Singh"},MOD(INT((ROW()-2)/20),15)+1)} -> Aditya Shah | C4: {=INDEX({"North","South","East","West","Central"},MOD(ROW()-2,5)+1)} -> East | D4: {=INDEX({"Electronics","Clothing","Furniture","Books","Office Supplies"},MOD(ROW()-2,5)+1)} -> Furniture | E4: =ROUND(500+MOD((ROW()-2)*137,44500),2) -> 774 | F4: =MOD((ROW()-2)*7,11)+1 -> 4 | G4: =CHOOSE(MOD(ROW()-2,8)+1,0,0.02,0.05,0.08,0.1,0.12,0.15,0.2) -> 0.05 | H4: =DATE(2025,1,1)+MOD(ROW()-2,365) -> 45660 | I4: =ROUND(E4*F4*(1-G4),2) -> 2941.2 | J4: =ROUND(I4*(0.08+MOD(ROW()-2,12)*0.02),2) -> 352.94 | K4: {=INDEX({"Amit","Neha","Riya","Karan","Pooja","Rahul","Meera","Vikram"},MOD(ROW()-2,8)+1)} -> Riya | L4: {=INDEX({"UPI","Credit Card","Debit Card","Cash","Net Banking"},MOD(ROW()-2,5)+1)} -> Debit Card | M4: {=INDEX({"Retail","Corporate","Education","Small Business"},MOD(ROW()-2,4)+1)} -> Education
A5: ="CUST"&TEXT(ROW()-1,"0000") -> CUST0004 | B5: {=INDEX({"Aarav","Vivaan","Aditya","Arjun","Kabir","Rohan","Ananya","Diya","Ishita","Meera","Riya","Pooja","Neha","Kavya","Aisha","Priya","Rahul","Karan","Vikram","Sahil"},MOD(ROW()-2,20)+1)&" "&INDEX({"Shah","Patel","Mehta","Desai","Joshi","Gupta","Verma","Sharma","Trivedi","Rana","Mishra","Kapoor","Iyer","Nair","Singh"},MOD(INT((ROW()-2)/20),15)+1)} -> Arjun Shah | C5: {=INDEX({"North","South","East","West","Central"},MOD(ROW()-2,5)+1)} -> West | D5: {=INDEX({"Electronics","Clothing","Furniture","Books","Office Supplies"},MOD(ROW()-2,5)+1)} -> Books | E5: =ROUND(500+MOD((ROW()-2)*137,44500),2) -> 911 | F5: =MOD((ROW()-2)*7,11)+1 -> 11 | G5: =CHOOSE(MOD(ROW()-2,8)+1,0,0.02,0.05,0.08,0.1,0.12,0.15,0.2) -> 0.08 | H5: =DATE(2025,1,1)+MOD(ROW()-2,365) -> 45661 | I5: =ROUND(E5*F5*(1-G5),2) -> 9219.32 | J5: =ROUND(I5*(0.08+MOD(ROW()-2,12)*0.02),2) -> 1290.7 | K5: {=INDEX({"Amit","Neha","Riya","Karan","Pooja","Rahul","Meera","Vikram"},MOD(ROW()-2,8)+1)} -> Karan | L5: {=INDEX({"UPI","Credit Card","Debit Card","Cash","Net Banking"},MOD(ROW()-2,5)+1)} -> Cash | M5: {=INDEX({"Retail","Corporate","Education","Small Business"},MOD(ROW()-2,4)+1)} -> Small Business
A6: ="CUST"&TEXT(ROW()-1,"0000") -> CUST0005 | B6: {=INDEX({"Aarav","Vivaan","Aditya","Arjun","Kabir","Rohan","Ananya","Diya","Ishita","Meera","Riya","Pooja","Neha","Kavya","Aisha","Priya","Rahul","Karan","Vikram","Sahil"},MOD(ROW()-2,20)+1)&" "&INDEX({"Shah","Patel","Mehta","Desai","Joshi","Gupta","Verma","Sharma","Trivedi","Rana","Mishra","Kapoor","Iyer","Nair","Singh"},MOD(INT((ROW()-2)/20),15)+1)} -> Kabir Shah | C6: {=INDEX({"North","South","East","West","Central"},MOD(ROW()-2,5)+1)} -> Central | D6: {=INDEX({"Electronics","Clothing","Furniture","Books","Office Supplies"},MOD(ROW()-2,5)+1)} -> Office Supplies | E6: =ROUND(500+MOD((ROW()-2)*137,44500),2) -> 1048 | F6: =MOD((ROW()-2)*7,11)+1 -> 7 | G6: =CHOOSE(MOD(ROW()-2,8)+1,0,0.02,0.05,0.08,0.1,0.12,0.15,0.2) -> 0.1 | H6: =DATE(2025,1,1)+MOD(ROW()-2,365) -> 45662 | I6: =ROUND(E6*F6*(1-G6),2) -> 6602.4 | J6: =ROUND(I6*(0.08+MOD(ROW()-2,12)*0.02),2) -> 1056.38 | K6: {=INDEX({"Amit","Neha","Riya","Karan","Pooja","Rahul","Meera","Vikram"},MOD(ROW()-2,8)+1)} -> Pooja | L6: {=INDEX({"UPI","Credit Card","Debit Card","Cash","Net Banking"},MOD(ROW()-2,5)+1)} -> Net Banking | M6: {=INDEX({"Retail","Corporate","Education","Small Business"},MOD(ROW()-2,4)+1)} -> Retail
A7: ="CUST"&TEXT(ROW()-1,"0000") -> CUST0006 | B7: {=INDEX({"Aarav","Vivaan","Aditya","Arjun","Kabir","Rohan","Ananya","Diya","Ishita","Meera","Riya","Pooja","Neha","Kavya","Aisha","Priya","Rahul","Karan","Vikram","Sahil"},MOD(ROW()-2,20)+1)&" "&INDEX({"Shah","Patel","Mehta","Desai","Joshi","Gupta","Verma","Sharma","Trivedi","Rana","Mishra","Kapoor","Iyer","Nair","Singh"},MOD(INT((ROW()-2)/20),15)+1)} -> Rohan Shah | C7: {=INDEX({"North","South","East","West","Central"},MOD(ROW()-2,5)+1)} -> North | D7: {=INDEX({"Electronics","Clothing","Furniture","Books","Office Supplies"},MOD(ROW()-2,5)+1)} -> Electronics | E7: =ROUND(500+MOD((ROW()-2)*137,44500),2) -> 1185 | F7: =MOD((ROW()-2)*7,11)+1 -> 3 | G7: =CHOOSE(MOD(ROW()-2,8)+1,0,0.02,0.05,0.08,0.1,0.12,0.15,0.2) -> 0.12 | H7: =DATE(2025,1,1)+MOD(ROW()-2,365) -> 45663 | I7: =ROUND(E7*F7*(1-G7),2) -> 3128.4 | J7: =ROUND(I7*(0.08+MOD(ROW()-2,12)*0.02),2) -> 563.11 | K7: {=INDEX({"Amit","Neha","Riya","Karan","Pooja","Rahul","Meera","Vikram"},MOD(ROW()-2,8)+1)} -> Rahul | L7: {=INDEX({"UPI","Credit Card","Debit Card","Cash","Net Banking"},MOD(ROW()-2,5)+1)} -> UPI | M7: {=INDEX({"Retail","Corporate","Education","Small Business"},MOD(ROW()-2,4)+1)} -> Corporate
A8: ="CUST"&TEXT(ROW()-1,"0000") -> CUST0007 | B8: {=INDEX({"Aarav","Vivaan","Aditya","Arjun","Kabir","Rohan","Ananya","Diya","Ishita","Meera","Riya","Pooja","Neha","Kavya","Aisha","Priya","Rahul","Karan","Vikram","Sahil"},MOD(ROW()-2,20)+1)&" "&INDEX({"Shah","Patel","Mehta","Desai","Joshi","Gupta","Verma","Sharma","Trivedi","Rana","Mishra","Kapoor","Iyer","Nair","Singh"},MOD(INT((ROW()-2)/20),15)+1)} -> Ananya Shah | C8: {=INDEX({"North","South","East","West","Central"},MOD(ROW()-2,5)+1)} -> South | D8: {=INDEX({"Electronics","Clothing","Furniture","Books","Office Supplies"},MOD(ROW()-2,5)+1)} -> Clothing | E8: =ROUND(500+MOD((ROW()-2)*137,44500),2) -> 1322 | F8: =MOD((ROW()-2)*7,11)+1 -> 10 | G8: =CHOOSE(MOD(ROW()-2,8)+1,0,0.02,0.05,0.08,0.1,0.12,0.15,0.2) -> 0.15 | H8: =DATE(2025,1,1)+MOD(ROW()-2,365) -> 45664 | I8: =ROUND(E8*F8*(1-G8),2) -> 11237 | J8: =ROUND(I8*(0.08+MOD(ROW()-2,12)*0.02),2) -> 2247.4 | K8: {=INDEX({"Amit","Neha","Riya","Karan","Pooja","Rahul","Meera","Vikram"},MOD(ROW()-2,8)+1)} -> Meera | L8: {=INDEX({"UPI","Credit Card","Debit Card","Cash","Net Banking"},MOD(ROW()-2,5)+1)} -> Credit Card | M8: {=INDEX({"Retail","Corporate","Education","Small Business"},MOD(ROW()-2,4)+1)} -> Education
A9: ="CUST"&TEXT(ROW()-1,"0000") -> CUST0008 | B9: {=INDEX({"Aarav","Vivaan","Aditya","Arjun","Kabir","Rohan","Ananya","Diya","Ishita","Meera","Riya","Pooja","Neha","Kavya","Aisha","Priya","Rahul","Karan","Vikram","Sahil"},MOD(ROW()-2,20)+1)&" "&INDEX({"Shah","Patel","Mehta","Desai","Joshi","Gupta","Verma","Sharma","Trivedi","Rana","Mishra","Kapoor","Iyer","Nair","Singh"},MOD(INT((ROW()-2)/20),15)+1)} -> Diya Shah | C9: {=INDEX({"North","South","East","West","Central"},MOD(ROW()-2,5)+1)} -> East | D9: {=INDEX({"Electronics","Clothing","Furniture","Books","Office Supplies"},MOD(ROW()-2,5)+1)} -> Furniture | E9: =ROUND(500+MOD((ROW()-2)*137,44500),2) -> 1459 | F9: =MOD((ROW()-2)*7,11)+1 -> 6 | G9: =CHOOSE(MOD(ROW()-2,8)+1,0,0.02,0.05,0.08,0.1,0.12,0.15,0.2) -> 0.2 | H9: =DATE(2025,1,1)+MOD(ROW()-2,365) -> 45665 | I9: =ROUND(E9*F9*(1-G9),2) -> 7003.2 | J9: =ROUND(I9*(0.08+MOD(ROW()-2,12)*0.02),2) -> 1540.7 | K9: {=INDEX({"Amit","Neha","Riya","Karan","Pooja","Rahul","Meera","Vikram"},MOD(ROW()-2,8)+1)} -> Vikram | L9: {=INDEX({"UPI","Credit Card","Debit Card","Cash","Net Banking"},MOD(ROW()-2,5)+1)} -> Debit Card | M9: {=INDEX({"Retail","Corporate","Education","Small Business"},MOD(ROW()-2,4)+1)} -> Small Business
A10: ="CUST"&TEXT(ROW()-1,"0000") -> CUST0009 | B10: {=INDEX({"Aarav","Vivaan","Aditya","Arjun","Kabir","Rohan","Ananya","Diya","Ishita","Meera","Riya","Pooja","Neha","Kavya","Aisha","Priya","Rahul","Karan","Vikram","Sahil"},MOD(ROW()-2,20)+1)&" "&INDEX({"Shah","Patel","Mehta","Desai","Joshi","Gupta","Verma","Sharma","Trivedi","Rana","Mishra","Kapoor","Iyer","Nair","Singh"},MOD(INT((ROW()-2)/20),15)+1)} -> Ishita Shah | C10: {=INDEX({"North","South","East","West","Central"},MOD(ROW()-2,5)+1)} -> West | D10: {=INDEX({"Electronics","Clothing","Furniture","Books","Office Supplies"},MOD(ROW()-2,5)+1)} -> Books | E10: =ROUND(500+MOD((ROW()-2)*137,44500),2) -> 1596 | F10: =MOD((ROW()-2)*7,11)+1 -> 2 | G10: =CHOOSE(MOD(ROW()-2,8)+1,0,0.02,0.05,0.08,0.1,0.12,0.15,0.2) -> 0 | H10: =DATE(2025,1,1)+MOD(ROW()-2,365) -> 45666 | I10: =ROUND(E10*F10*(1-G10),2) -> 3192 | J10: =ROUND(I10*(0.08+MOD(ROW()-2,12)*0.02),2) -> 766.08 | K10: {=INDEX({"Amit","Neha","Riya","Karan","Pooja","Rahul","Meera","Vikram"},MOD(ROW()-2,8)+1)} -> Amit | L10: {=INDEX({"UPI","Credit Card","Debit Card","Cash","Net Banking"},MOD(ROW()-2,5)+1)} -> Cash | M10: {=INDEX({"Retail","Corporate","Education","Small Business"},MOD(ROW()-2,4)+1)} -> Retail
A11: ="CUST"&TEXT(ROW()-1,"0000") -> CUST0010 | B11: {=INDEX({"Aarav","Vivaan","Aditya","Arjun","Kabir","Rohan","Ananya","Diya","Ishita","Meera","Riya","Pooja","Neha","Kavya","Aisha","Priya","Rahul","Karan","Vikram","Sahil"},MOD(ROW()-2,20)+1)&" "&INDEX({"Shah","Patel","Mehta","Desai","Joshi","Gupta","Verma","Sharma","Trivedi","Rana","Mishra","Kapoor","Iyer","Nair","Singh"},MOD(INT((ROW()-2)/20),15)+1)} -> Meera Shah | C11: {=INDEX({"North","South","East","West","Central"},MOD(ROW()-2,5)+1)} -> Central | D11: {=INDEX({"Electronics","Clothing","Furniture","Books","Office Supplies"},MOD(ROW()-2,5)+1)} -> Office Supplies | E11: =ROUND(500+MOD((ROW()-2)*137,44500),2) -> 1733 | F11: =MOD((ROW()-2)*7,11)+1 -> 9 | G11: =CHOOSE(MOD(ROW()-2,8)+1,0,0.02,0.05,0.08,0.1,0.12,0.15,0.2) -> 0.02 | H11: =DATE(2025,1,1)+MOD(ROW()-2,365) -> 45667 | I11: =ROUND(E11*F11*(1-G11),2) -> 15285.06 | J11: =ROUND(I11*(0.08+MOD(ROW()-2,12)*0.02),2) -> 3974.12 | K11: {=INDEX({"Amit","Neha","Riya","Karan","Pooja","Rahul","Meera","Vikram"},MOD(ROW()-2,8)+1)} -> Neha | L11: {=INDEX({"UPI","Credit Card","Debit Card","Cash","Net Banking"},MOD(ROW()-2,5)+1)} -> Net Banking | M11: {=INDEX({"Retail","Corporate","Education","Small Business"},MOD(ROW()-2,4)+1)} -> Corporate
A12: ="CUST"&TEXT(ROW()-1,"0000") -> CUST0011 | B12: {=INDEX({"Aarav","Vivaan","Aditya","Arjun","Kabir","Rohan","Ananya","Diya","Ishita","Meera","Riya","Pooja","Neha","Kavya","Aisha","Priya","Rahul","Karan","Vikram","Sahil"},MOD(ROW()-2,20)+1)&" "&INDEX({"Shah","Patel","Mehta","Desai","Joshi","Gupta","Verma","Sharma","Trivedi","Rana","Mishra","Kapoor","Iyer","Nair","Singh"},MOD(INT((ROW()-2)/20),15)+1)} -> Riya Shah | C12: {=INDEX({"North","South","East","West","Central"},MOD(ROW()-2,5)+1)} -> North | D12: {=INDEX({"Electronics","Clothing","Furniture","Books","Office Supplies"},MOD(ROW()-2,5)+1)} -> Electronics | E12: =ROUND(500+MOD((ROW()-2)*137,44500),2) -> 1870 | F12: =MOD((ROW()-2)*7,11)+1 -> 5 | G12: =CHOOSE(MOD(ROW()-2,8)+1,0,0.02,0.05,0.08,0.1,0.12,0.15,0.2) -> 0.05 | H12: =DATE(2025,1,1)+MOD(ROW()-2,365) -> 45668 | I12: =ROUND(E12*F12*(1-G12),2) -> 8882.5 | J12: =ROUND(I12*(0.08+MOD(ROW()-2,12)*0.02),2) -> 2487.1 | K12: {=INDEX({"Amit","Neha","Riya","Karan","Pooja","Rahul","Meera","Vikram"},MOD(ROW()-2,8)+1)} -> Riya | L12: {=INDEX({"UPI","Credit Card","Debit Card","Cash","Net Banking"},MOD(ROW()-2,5)+1)} -> UPI | M12: {=INDEX({"Retail","Corporate","Education","Small Business"},MOD(ROW()-2,4)+1)} -> Education
A13: ="CUST"&TEXT(ROW()-1,"0000") -> CUST0012 | B13: {=INDEX({"Aarav","Vivaan","Aditya","Arjun","Kabir","Rohan","Ananya","Diya","Ishita","Meera","Riya","Pooja","Neha","Kavya","Aisha","Priya","Rahul","Karan","Vikram","Sahil"},MOD(ROW()-2,20)+1)&" "&INDEX({"Shah","Patel","Mehta","Desai","Joshi","Gupta","Verma","Sharma","Trivedi","Rana","Mishra","Kapoor","Iyer","Nair","Singh"},MOD(INT((ROW()-2)/20),15)+1)} -> Pooja Shah | C13: {=INDEX({"North","South","East","West","Central"},MOD(ROW()-2,5)+1)} -> South | D13: {=INDEX({"Electronics","Clothing","Furniture","Books","Office Supplies"},MOD(ROW()-2,5)+1)} -> Clothing | E13: =ROUND(500+MOD((ROW()-2)*137,44500),2) -> 2007 | F13: =MOD((ROW()-2)*7,11)+1 -> 1 | G13: =CHOOSE(MOD(ROW()-2,8)+1,0,0.02,0.05,0.08,0.1,0.12,0.15,0.2) -> 0.08 | H13: =DATE(2025,1,1)+MOD(ROW()-2,365) -> 45669 | I13: =ROUND(E13*F13*(1-G13),2) -> 1846.44 | J13: =ROUND(I13*(0.08+MOD(ROW()-2,12)*0.02),2) -> 553.93 | K13: {=INDEX({"Amit","Neha","Riya","Karan","Pooja","Rahul","Meera","Vikram"},MOD(ROW()-2,8)+1)} -> Karan | L13: {=INDEX({"UPI","Credit Card","Debit Card","Cash","Net Banking"},MOD(ROW()-2,5)+1)} -> Credit Card | M13: {=INDEX({"Retail","Corporate","Education","Small Business"},MOD(ROW()-2,4)+1)} -> Small Business
... A15: ="CUST"&TEXT(ROW()-1,"0000") -> CUST0014 | B15: {=INDEX({"Aarav","Vivaan","Aditya","Arjun","Kabir","Rohan","Ananya","Diya","Ishita","Meera","Riya","Pooja","Neha","Kavya","Aisha","Priya","Rahul","Karan","Vikram","Sahil"},MOD(ROW()-2,20)+1)&" "&INDEX({"Shah","Patel","Mehta","Desai","Joshi","Gupta","Verma","Sharma","Trivedi","Rana","Mishra","Kapoor","Iyer","Nair","Singh"},MOD(INT((ROW()-2)/20),15)+1)} -> Kavya Shah | C15: {=INDEX({"North","South","East","West","Central"},MOD(ROW()-2,5)+1)} -> West | D15: {=INDEX({"Electronics","Clothing","Furniture","Books","Office Supplies"},MOD(ROW()-2,5)+1)} -> Books | E15: =ROUND(500+MOD((ROW()-2)*137,44500),2) -> 2281 | F15: =MOD((ROW()-2)*7,11)+1 -> 4 | G15: =CHOOSE(MOD(ROW()-2,8)+1,0,0.02,0.05,0.08,0.1,0.12,0.15,0.2) -> 0.12 | H15: =DATE(2025,1,1)+MOD(ROW()-2,365) -> 45671 | I15: =ROUND(E15*F15*(1-G15),2) -> 8029.12 | J15: =ROUND(I15*(0.08+MOD(ROW()-2,12)*0.02),2) -> 802.91 | K15: {=INDEX({"Amit","Neha","Riya","Karan","Pooja","Rahul","Meera","Vikram"},MOD(ROW()-2,8)+1)} -> Rahul | L15: {=INDEX({"UPI","Credit Card","Debit Card","Cash","Net Banking"},MOD(ROW()-2,5)+1)} -> Cash | M15: {=INDEX({"Retail","Corporate","Education","Small Business"},MOD(ROW()-2,4)+1)} -> Corporate
A16: ="CUST"&TEXT(ROW()-1,"0000") -> CUST0015 | B16: Vikram Patel | C16: {=INDEX({"North","South","East","West","Central"},MOD(ROW()-2,5)+1)} -> Central | D16: {=INDEX({"Electronics","Clothing","Furniture","Books","Office Supplies"},MOD(ROW()-2,5)+1)} -> Office Supplies | E16: =ROUND(500+MOD((ROW()-2)*137,44500),2) -> 2418 | F16: =MOD((ROW()-2)*7,11)+1 -> 11 | G16: =CHOOSE(MOD(ROW()-2,8)+1,0,0.02,0.05,0.08,0.1,0.12,0.15,0.2) -> 0.15 | H16: =DATE(2025,1,1)+MOD(ROW()-2,365) -> 45672 | I16: =ROUND(E16*F16*(1-G16),2) -> 22608.3 | J16: =ROUND(I16*(0.08+MOD(ROW()-2,12)*0.02),2) -> 2713 | K16: {=INDEX({"Amit","Neha","Riya","Karan","Pooja","Rahul","Meera","Vikram"},MOD(ROW()-2,8)+1)} -> Meera | L16: {=INDEX({"UPI","Credit Card","Debit Card","Cash","Net Banking"},MOD(ROW()-2,5)+1)} -> Net Banking | M16: {=INDEX({"Retail","Corporate","Education","Small Business"},MOD(ROW()-2,4)+1)} -> Education
A17: ="CUST"&TEXT(ROW()-1,"0000") -> CUST0016 | B17: {=INDEX({"Aarav","Vivaan","Aditya","Arjun","Kabir","Rohan","Ananya","Diya","Ishita","Meera","Riya","Pooja","Neha","Kavya","Aisha","Priya","Rahul","Karan","Vikram","Sahil"},MOD(ROW()-2,20)+1)&" "&INDEX({"Shah","Patel","Mehta","Desai","Joshi","Gupta","Verma","Sharma","Trivedi","Rana","Mishra","Kapoor","Iyer","Nair","Singh"},MOD(INT((ROW()-2)/20),15)+1)} -> Priya Shah | C17: {=INDEX({"North","South","East","West","Central"},MOD(ROW()-2,5)+1)} -> North | D17: {=INDEX({"Electronics","Clothing","Furniture","Books","Office Supplies"},MOD(ROW()-2,5)+1)} -> Electronics | E17: =ROUND(500+MOD((ROW()-2)*137,44500),2) -> 2555 | F17: =MOD((ROW()-2)*7,11)+1 -> 7 | G17: =CHOOSE(MOD(ROW()-2,8)+1,0,0.02,0.05,0.08,0.1,0.12,0.15,0.2) -> 0.2 | H17: 45703 | I17: =ROUND(E17*F17*(1-G17),2) -> 14308 | J17: =ROUND(I17*(0.08+MOD(ROW()-2,12)*0.02),2) -> 2003.12 | K17: {=INDEX({"Amit","Neha","Riya","Karan","Pooja","Rahul","Meera","Vikram"},MOD(ROW()-2,8)+1)} -> Vikram | L17: {=INDEX({"UPI","Credit Card","Debit Card","Cash","Net Banking"},MOD(ROW()-2,5)+1)} -> UPI | M17: {=INDEX({"Retail","Corporate","Education","Small Business"},MOD(ROW()-2,4)+1)} -> Small Business
A18: ="CUST"&TEXT(ROW()-1,"0000") -> CUST0017 | B18: {=INDEX({"Aarav","Vivaan","Aditya","Arjun","Kabir","Rohan","Ananya","Diya","Ishita","Meera","Riya","Pooja","Neha","Kavya","Aisha","Priya","Rahul","Karan","Vikram","Sahil"},MOD(ROW()-2,20)+1)&" "&INDEX({"Shah","Patel","Mehta","Desai","Joshi","Gupta","Verma","Sharma","Trivedi","Rana","Mishra","Kapoor","Iyer","Nair","Singh"},MOD(INT((ROW()-2)/20),15)+1)} -> Rahul Shah | C18: {=INDEX({"North","South","East","West","Central"},MOD(ROW()-2,5)+1)} -> South | D18: {=INDEX({"Electronics","Clothing","Furniture","Books","Office Supplies"},MOD(ROW()-2,5)+1)} -> Clothing | E18: 6802 | F18: =MOD((ROW()-2)*7,11)+1 -> 3 | G18: =CHOOSE(MOD(ROW()-2,8)+1,0,0.02,0.05,0.08,0.1,0.12,0.15,0.2) -> 0 | H18: =DATE(2025,1,1)+MOD(ROW()-2,365) -> 45674 | I18: =ROUND(E18*F18*(1-G18),2) -> 20406 | J18: =ROUND(I18*(0.08+MOD(ROW()-2,12)*0.02),2) -> 3264.96 | K18: {=INDEX({"Amit","Neha","Riya","Karan","Pooja","Rahul","Meera","Vikram"},MOD(ROW()-2,8)+1)} -> Amit | L18: {=INDEX({"UPI","Credit Card","Debit Card","Cash","Net Banking"},MOD(ROW()-2,5)+1)} -> Credit Card | M18: {=INDEX({"Retail","Corporate","Education","Small Business"},MOD(ROW()-2,4)+1)} -> Retail
A19: ="CUST"&TEXT(ROW()-1,"0000") -> CUST0018 | B19: {=INDEX({"Aarav","Vivaan","Aditya","Arjun","Kabir","Rohan","Ananya","Diya","Ishita","Meera","Riya","Pooja","Neha","Kavya","Aisha","Priya","Rahul","Karan","Vikram","Sahil"},MOD(ROW()-2,20)+1)&" "&INDEX({"Shah","Patel","Mehta","Desai","Joshi","Gupta","Verma","Sharma","Trivedi","Rana","Mishra","Kapoor","Iyer","Nair","Singh"},MOD(INT((ROW()-2)/20),15)+1)} -> Karan Shah | C19: {=INDEX({"North","South","East","West","Central"},MOD(ROW()-2,5)+1)} -> East | D19: {=INDEX({"Electronics","Clothing","Furniture","Books","Office Supplies"},MOD(ROW()-2,5)+1)} -> Furniture | E19: =ROUND(500+MOD((ROW()-2)*137,44500),2) -> 2829 | F19: =MOD((ROW()-2)*7,11)+1 -> 10 | G19: =CHOOSE(MOD(ROW()-2,8)+1,0,0.02,0.05,0.08,0.1,0.12,0.15,0.2) -> 0.02 | H19: =DATE(2025,1,1)+MOD(ROW()-2,365) -> 45675 | I19: =ROUND(E19*F19*(1-G19),2) -> 27724.2 | J19: =ROUND(I19*(0.08+MOD(ROW()-2,12)*0.02),2) -> 4990.36 | K19: {=INDEX({"Amit","Neha","Riya","Karan","Pooja","Rahul","Meera","Vikram"},MOD(ROW()-2,8)+1)} -> Neha | L19: {=INDEX({"UPI","Credit Card","Debit Card","Cash","Net Banking"},MOD(ROW()-2,5)+1)} -> Debit Card | M19: {=INDEX({"Retail","Corporate","Education","Small Business"},MOD(ROW()-2,4)+1)} -> Corporate
A20: ="CUST"&TEXT(ROW()-1,"0000") -> CUST0019 | B20: {=INDEX({"Aarav","Vivaan","Aditya","Arjun","Kabir","Rohan","Ananya","Diya","Ishita","Meera","Riya","Pooja","Neha","Kavya","Aisha","Priya","Rahul","Karan","Vikram","Sahil"},MOD(ROW()-2,20)+1)&" "&INDEX({"Shah","Patel","Mehta","Desai","Joshi","Gupta","Verma","Sharma","Trivedi","Rana","Mishra","Kapoor","Iyer","Nair","Singh"},MOD(INT((ROW()-2)/20),15)+1)} -> Vikram Shah | C20: {=INDEX({"North","South","East","West","Central"},MOD(ROW()-2,5)+1)} -> West | D20: {=INDEX({"Electronics","Clothing","Furniture","Books","Office Supplies"},MOD(ROW()-2,5)+1)} -> Books | E20: =ROUND(500+MOD((ROW()-2)*137,44500),2) -> 2966 | F20: =MOD((ROW()-2)*7,11)+1 -> 6 | G20: =CHOOSE(MOD(ROW()-2,8)+1,0,0.02,0.05,0.08,0.1,0.12,0.15,0.2) -> 0.05 | H20: =DATE(2025,1,1)+MOD(ROW()-2,365) -> 45676 | I20: =ROUND(E20*F20*(1-G20),2) -> 16906.2 | J20: =ROUND(I20*(0.08+MOD(ROW()-2,12)*0.02),2) -> 3381.24 | K20: {=INDEX({"Amit","Neha","Riya","Karan","Pooja","Rahul","Meera","Vikram"},MOD(ROW()-2,8)+1)} -> Riya | L20: {=INDEX({"UPI","Credit Card","Debit Card","Cash","Net Banking"},MOD(ROW()-2,5)+1)} -> Cash | M20: {=INDEX({"Retail","Corporate","Education","Small Business"},MOD(ROW()-2,4)+1)} -> Education
A21: ="CUST"&TEXT(ROW()-1,"0000") -> CUST0020 | B21: {=INDEX({"Aarav","Vivaan","Aditya","Arjun","Kabir","Rohan","Ananya","Diya","Ishita","Meera","Riya","Pooja","Neha","Kavya","Aisha","Priya","Rahul","Karan","Vikram","Sahil"},MOD(ROW()-2,20)+1)&" "&INDEX({"Shah","Patel","Mehta","Desai","Joshi","Gupta","Verma","Sharma","Trivedi","Rana","Mishra","Kapoor","Iyer","Nair","Singh"},MOD(INT((ROW()-2)/20),15)+1)} -> Sahil Shah | C21: {=INDEX({"North","South","East","West","Central"},MOD(ROW()-2,5)+1)} -> Central | D21: {=INDEX({"Electronics","Clothing","Furniture","Books","Office Supplies"},MOD(ROW()-2,5)+1)} -> Office Supplies | E21: =ROUND(500+MOD((ROW()-2)*137,44500),2) -> 3103 | F21: =MOD((ROW()-2)*7,11)+1 -> 2 | G21: =CHOOSE(MOD(ROW()-2,8)+1,0,0.02,0.05,0.08,0.1,0.12,0.15,0.2) -> 0.08 | H21: =DATE(2025,1,1)+MOD(ROW()-2,365) -> 45677 | I21: =ROUND(E21*F21*(1-G21),2) -> 5709.52 | J21: =ROUND(I21*(0.08+MOD(ROW()-2,12)*0.02),2) -> 1256.09 | K21: {=INDEX({"Amit","Neha","Riya","Karan","Pooja","Rahul","Meera","Vikram"},MOD(ROW()-2,8)+1)} -> Karan | L21: {=INDEX({"UPI","Credit Card","Debit Card","Cash","Net Banking"},MOD(ROW()-2,5)+1)} -> Net Banking | M21: {=INDEX({"Retail","Corporate","Education","Small Business"},MOD(ROW()-2,4)+1)} -> Small Business
A22: ="CUST"&TEXT(ROW()-1,"0000") -> CUST0021 | B22: {=INDEX({"Aarav","Vivaan","Aditya","Arjun","Kabir","Rohan","Ananya","Diya","Ishita","Meera","Riya","Pooja","Neha","Kavya","Aisha","Priya","Rahul","Karan","Vikram","Sahil"},MOD(ROW()-2,20)+1)&" "&INDEX({"Shah","Patel","Mehta","Desai","Joshi","Gupta","Verma","Sharma","Trivedi","Rana","Mishra","Kapoor","Iyer","Nair","Singh"},MOD(INT((ROW()-2)/20),15)+1)} -> Aarav Patel | C22: {=INDEX({"North","South","East","West","Central"},MOD(ROW()-2,5)+1)} -> North | D22: {=INDEX({"Electronics","Clothing","Furniture","Books","Office Supplies"},MOD(ROW()-2,5)+1)} -> Electronics | E22: =ROUND(500+MOD((ROW()-2)*137,44500),2) -> 3240 | F22: =MOD((ROW()-2)*7,11)+1 -> 9 | G22: =CHOOSE(MOD(ROW()-2,8)+1,0,0.02,0.05,0.08,0.1,0.12,0.15,0.2) -> 0.1 | H22: =DATE(2025,1,1)+MOD(ROW()-2,365) -> 45678 | I22: =ROUND(E22*F22*(1-G22),2) -> 26244 | J22: =ROUND(I22*(0.08+MOD(ROW()-2,12)*0.02),2) -> 6298.56 | K22: {=INDEX({"Amit","Neha","Riya","Karan","Pooja","Rahul","Meera","Vikram"},MOD(ROW()-2,8)+1)} -> Pooja | L22: {=INDEX({"UPI","Credit Card","Debit Card","Cash","Net Banking"},MOD(ROW()-2,5)+1)} -> UPI | M22: {=INDEX({"Retail","Corporate","Education","Small Business"},MOD(ROW()-2,4)+1)} -> Retail
A23: ="CUST"&TEXT(ROW()-1,"0000") -> CUST0022 | B23: {=INDEX({"Aarav","Vivaan","Aditya","Arjun","Kabir","Rohan","Ananya","Diya","Ishita","Meera","Riya","Pooja","Neha","Kavya","Aisha","Priya","Rahul","Karan","Vikram","Sahil"},MOD(ROW()-2,20)+1)&" "&INDEX({"Shah","Patel","Mehta","Desai","Joshi","Gupta","Verma","Sharma","Trivedi","Rana","Mishra","Kapoor","Iyer","Nair","Singh"},MOD(INT((ROW()-2)/20),15)+1)} -> Vivaan Patel | C23: {=INDEX({"North","South","East","West","Central"},MOD(ROW()-2,5)+1)} -> South | D23: {=INDEX({"Electronics","Clothing","Furniture","Books","Office Supplies"},MOD(ROW()-2,5)+1)} -> Clothing | E23: =ROUND(500+MOD((ROW()-2)*137,44500),2) -> 3377 | F23: =MOD((ROW()-2)*7,11)+1 -> 5 | G23: =CHOOSE(MOD(ROW()-2,8)+1,0,0.02,0.05,0.08,0.1,0.12,0.15,0.2) -> 0.12 | H23: =DATE(2025,1,1)+MOD(ROW()-2,365) -> 45679 | I23: =ROUND(E23*F23*(1-G23),2) -> 14858.8 | J23: =ROUND(I23*(0.08+MOD(ROW()-2,12)*0.02),2) -> 3863.29 | K23: {=INDEX({"Amit","Neha","Riya","Karan","Pooja","Rahul","Meera","Vikram"},MOD(ROW()-2,8)+1)} -> Rahul | L23: {=INDEX({"UPI","Credit Card","Debit Card","Cash","Net Banking"},MOD(ROW()-2,5)+1)} -> Credit Card | M23: {=INDEX({"Retail","Corporate","Education","Small Business"},MOD(ROW()-2,4)+1)} -> Corporate
A24: ="CUST"&TEXT(ROW()-1,"0000") -> CUST0023 | B24: {=INDEX({"Aarav","Vivaan","Aditya","Arjun","Kabir","Rohan","Ananya","Diya","Ishita","Meera","Riya","Pooja","Neha","Kavya","Aisha","Priya","Rahul","Karan","Vikram","Sahil"},MOD(ROW()-2,20)+1)&" "&INDEX({"Shah","Patel","Mehta","Desai","Joshi","Gupta","Verma","Sharma","Trivedi","Rana","Mishra","Kapoor","Iyer","Nair","Singh"},MOD(INT((ROW()-2)/20),15)+1)} -> Aditya Patel | C24: {=INDEX({"North","South","East","West","Central"},MOD(ROW()-2,5)+1)} -> East | D24: {=INDEX({"Electronics","Clothing","Furniture","Books","Office Supplies"},MOD(ROW()-2,5)+1)} -> Furniture | E24: =ROUND(500+MOD((ROW()-2)*137,44500),2) -> 3514 | F24: =MOD((ROW()-2)*7,11)+1 -> 1 | G24: =CHOOSE(MOD(ROW()-2,8)+1,0,0.02,0.05,0.08,0.1,0.12,0.15,0.2) -> 0.15 | H24: =DATE(2025,1,1)+MOD(ROW()-2,365) -> 45680 | I24: =ROUND(E24*F24*(1-G24),2) -> 2986.9 | J24: =ROUND(I24*(0.08+MOD(ROW()-2,12)*0.02),2) -> 836.33 | K24: {=INDEX({"Amit","Neha","Riya","Karan","Pooja","Rahul","Meera","Vikram"},MOD(ROW()-2,8)+1)} -> Meera | L24: {=INDEX({"UPI","Credit Card","Debit Card","Cash","Net Banking"},MOD(ROW()-2,5)+1)} -> Debit Card | M24: {=INDEX({"Retail","Corporate","Education","Small Business"},MOD(ROW()-2,4)+1)} -> Education
A25: ="CUST"&TEXT(ROW()-1,"0000") -> CUST0024 | B25: {=INDEX({"Aarav","Vivaan","Aditya","Arjun","Kabir","Rohan","Ananya","Diya","Ishita","Meera","Riya","Pooja","Neha","Kavya","Aisha","Priya","Rahul","Karan","Vikram","Sahil"},MOD(ROW()-2,20)+1)&" "&INDEX({"Shah","Patel","Mehta","Desai","Joshi","Gupta","Verma","Sharma","Trivedi","Rana","Mishra","Kapoor","Iyer","Nair","Singh"},MOD(INT((ROW()-2)/20),15)+1)} -> Arjun Patel | C25: {=INDEX({"North","South","East","West","Central"},MOD(ROW()-2,5)+1)} -> West | D25: {=INDEX({"Electronics","Clothing","Furniture","Books","Office Supplies"},MOD(ROW()-2,5)+1)} -> Books | E25: =ROUND(500+MOD((ROW()-2)*137,44500),2) -> 3651 | F25: 9 | G25: =CHOOSE(MOD(ROW()-2,8)+1,0,0.02,0.05,0.08,0.1,0.12,0.15,0.2) -> 0.2 | H25: =DATE(2025,1,1)+MOD(ROW()-2,365) -> 45681 | I25: =ROUND(E25*F25*(1-G25),2) -> 26287.2 | J25: =ROUND(I25*(0.08+MOD(ROW()-2,12)*0.02),2) -> 7886.16 | K25: {=INDEX({"Amit","Neha","Riya","Karan","Pooja","Rahul","Meera","Vikram"},MOD(ROW()-2,8)+1)} -> Vikram | L25: {=INDEX({"UPI","Credit Card","Debit Card","Cash","Net Banking"},MOD(ROW()-2,5)+1)} -> Cash | M25: {=INDEX({"Retail","Corporate","Education","Small Business"},MOD(ROW()-2,4)+1)} -> Small Business
A26: ="CUST"&TEXT(ROW()-1,"0000") -> CUST0025 | B26: {=INDEX({"Aarav","Vivaan","Aditya","Arjun","Kabir","Rohan","Ananya","Diya","Ishita","Meera","Riya","Pooja","Neha","Kavya","Aisha","Priya","Rahul","Karan","Vikram","Sahil"},MOD(ROW()-2,20)+1)&" "&INDEX({"Shah","Patel","Mehta","Desai","Joshi","Gupta","Verma","Sharma","Trivedi","Rana","Mishra","Kapoor","Iyer","Nair","Singh"},MOD(INT((ROW()-2)/20),15)+1)} -> Kabir Patel | C26: {=INDEX({"North","South","East","West","Central"},MOD(ROW()-2,5)+1)} -> Central | D26: {=INDEX({"Electronics","Clothing","Furniture","Books","Office Supplies"},MOD(ROW()-2,5)+1)} -> Office Supplies | E26: =ROUND(500+MOD((ROW()-2)*137,44500),2) -> 3788 | F26: =MOD((ROW()-2)*7,11)+1 -> 4 | G26: =CHOOSE(MOD(ROW()-2,8)+1,0,0.02,0.05,0.08,0.1,0.12,0.15,0.2) -> 0 | H26: =DATE(2025,1,1)+MOD(ROW()-2,365) -> 45682 | I26: =ROUND(E26*F26*(1-G26),2) -> 15152 | J26: =ROUND(I26*(0.08+MOD(ROW()-2,12)*0.02),2) -> 1212.16 | K26: {=INDEX({"Amit","Neha","Riya","Karan","Pooja","Rahul","Meera","Vikram"},MOD(ROW()-2,8)+1)} -> Amit | L26: {=INDEX({"UPI","Credit Card","Debit Card","Cash","Net Banking"},MOD(ROW()-2,5)+1)} -> Net Banking | M26: {=INDEX({"Retail","Corporate","Education","Small Business"},MOD(ROW()-2,4)+1)} -> Retail
A27: ="CUST"&TEXT(ROW()-1,"0000") -> CUST0026 | B27: {=INDEX({"Aarav","Vivaan","Aditya","Arjun","Kabir","Rohan","Ananya","Diya","Ishita","Meera","Riya","Pooja","Neha","Kavya","Aisha","Priya","Rahul","Karan","Vikram","Sahil"},MOD(ROW()-2,20)+1)&" "&INDEX({"Shah","Patel","Mehta","Desai","Joshi","Gupta","Verma","Sharma","Trivedi","Rana","Mishra","Kapoor","Iyer","Nair","Singh"},MOD(INT((ROW()-2)/20),15)+1)} -> Rohan Patel | C27: {=INDEX({"North","South","East","West","Central"},MOD(ROW()-2,5)+1)} -> North | D27: {=INDEX({"Electronics","Clothing","Furniture","Books","Office Supplies"},MOD(ROW()-2,5)+1)} -> Electronics | E27: =ROUND(500+MOD((ROW()-2)*137,44500),2) -> 3925 | F27: =MOD((ROW()-2)*7,11)+1 -> 11 | G27: =CHOOSE(MOD(ROW()-2,8)+1,0,0.02,0.05,0.08,0.1,0.12,0.15,0.2) -> 0.02 | H27: =DATE(2025,1,1)+MOD(ROW()-2,365) -> 45683 | I27: =ROUND(E27*F27*(1-G27),2) -> 42311.5 | J27: =ROUND(I27*(0.08+MOD(ROW()-2,12)*0.02),2) -> 4231.15 | K27: {=INDEX({"Amit","Neha","Riya","Karan","Pooja","Rahul","Meera","Vikram"},MOD(ROW()-2,8)+1)} -> Neha | L27: {=INDEX({"UPI","Credit Card","Debit Card","Cash","Net Banking"},MOD(ROW()-2,5)+1)} -> UPI | M27: {=INDEX({"Retail","Corporate","Education","Small Business"},MOD(ROW()-2,4)+1)} -> Corporate
A28: ="CUST"&TEXT(ROW()-1,"0000") -> CUST0027 | B28: {=INDEX({"Aarav","Vivaan","Aditya","Arjun","Kabir","Rohan","Ananya","Diya","Ishita","Meera","Riya","Pooja","Neha","Kavya","Aisha","Priya","Rahul","Karan","Vikram","Sahil"},MOD(ROW()-2,20)+1)&" "&INDEX({"Shah","Patel","Mehta","Desai","Joshi","Gupta","Verma","Sharma","Trivedi","Rana","Mishra","Kapoor","Iyer","Nair","Singh"},MOD(INT((ROW()-2)/20),15)+1)} -> Ananya Patel | C28: {=INDEX({"North","South","East","West","Central"},MOD(ROW()-2,5)+1)} -> South | D28: {=INDEX({"Electronics","Clothing","Furniture","Books","Office Supplies"},MOD(ROW()-2,5)+1)} -> Clothing | E28: =ROUND(500+MOD((ROW()-2)*137,44500),2) -> 4062 | F28: =MOD((ROW()-2)*7,11)+1 -> 7 | G28: =CHOOSE(MOD(ROW()-2,8)+1,0,0.02,0.05,0.08,0.1,0.12,0.15,0.2) -> 0.05 | H28: =DATE(2025,1,1)+MOD(ROW()-2,365) -> 45684 | I28: =ROUND(E28*F28*(1-G28),2) -> 27012.3 | J28: =ROUND(I28*(0.08+MOD(ROW()-2,12)*0.02),2) -> 3241.48 | K28: {=INDEX({"Amit","Neha","Riya","Karan","Pooja","Rahul","Meera","Vikram"},MOD(ROW()-2,8)+1)} -> Riya | L28: {=INDEX({"UPI","Credit Card","Debit Card","Cash","Net Banking"},MOD(ROW()-2,5)+1)} -> Credit Card | M28: {=INDEX({"Retail","Corporate","Education","Small Business"},MOD(ROW()-2,4)+1)} -> Education
A29: ="CUST"&TEXT(ROW()-1,"0000") -> CUST0028 | B29: {=INDEX({"Aarav","Vivaan","Aditya","Arjun","Kabir","Rohan","Ananya","Diya","Ishita","Meera","Riya","Pooja","Neha","Kavya","Aisha","Priya","Rahul","Karan","Vikram","Sahil"},MOD(ROW()-2,20)+1)&" "&INDEX({"Shah","Patel","Mehta","Desai","Joshi","Gupta","Verma","Sharma","Trivedi","Rana","Mishra","Kapoor","Iyer","Nair","Singh"},MOD(INT((ROW()-2)/20),15)+1)} -> Diya Patel | C29: {=INDEX({"North","South","East","West","Central"},MOD(ROW()-2,5)+1)} -> East | D29: {=INDEX({"Electronics","Clothing","Furniture","Books","Office Supplies"},MOD(ROW()-2,5)+1)} -> Furniture | E29: =ROUND(500+MOD((ROW()-2)*137,44500),2) -> 4199 | F29: =MOD((ROW()-2)*7,11)+1 -> 3 | G29: =CHOOSE(MOD(ROW()-2,8)+1,0,0.02,0.05,0.08,0.1,0.12,0.15,0.2) -> 0.08 | H29: =DATE(2025,1,1)+MOD(ROW()-2,365) -> 45685 | I29: =ROUND(E29*F29*(1-G29),2) -> 11589.24 | J29: =ROUND(I29*(0.08+MOD(ROW()-2,12)*0.02),2) -> 1622.49 | K29: {=INDEX({"Amit","Neha","Riya","Karan","Pooja","Rahul","Meera","Vikram"},MOD(ROW()-2,8)+1)} -> Karan | L29: {=INDEX({"UPI","Credit Card","Debit Card","Cash","Net Banking"},MOD(ROW()-2,5)+1)} -> Debit Card | M29: {=INDEX({"Retail","Corporate","Education","Small Business"},MOD(ROW()-2,4)+1)} -> Small Business
A30: ="CUST"&TEXT(ROW()-1,"0000") -> CUST0029 | B30: {=INDEX({"Aarav","Vivaan","Aditya","Arjun","Kabir","Rohan","Ananya","Diya","Ishita","Meera","Riya","Pooja","Neha","Kavya","Aisha","Priya","Rahul","Karan","Vikram","Sahil"},MOD(ROW()-2,20)+1)&" "&INDEX({"Shah","Patel","Mehta","Desai","Joshi","Gupta","Verma","Sharma","Trivedi","Rana","Mishra","Kapoor","Iyer","Nair","Singh"},MOD(INT((ROW()-2)/20),15)+1)} -> Ishita Patel | C30: {=INDEX({"North","South","East","West","Central"},MOD(ROW()-2,5)+1)} -> West | D30: {=INDEX({"Electronics","Clothing","Furniture","Books","Office Supplies"},MOD(ROW()-2,5)+1)} -> Books | E30: =ROUND(500+MOD((ROW()-2)*137,44500),2) -> 4336 | F30: =MOD((ROW()-2)*7,11)+1 -> 10 | G30: =CHOOSE(MOD(ROW()-2,8)+1,0,0.02,0.05,0.08,0.1,0.12,0.15,0.2) -> 0.1 | H30: =DATE(2025,1,1)+MOD(ROW()-2,365) -> 45686 | I30: =ROUND(E30*F30*(1-G30),2) -> 39024 | J30: =ROUND(I30*(0.08+MOD(ROW()-2,12)*0.02),2) -> 6243.84 | K30: {=INDEX({"Amit","Neha","Riya","Karan","Pooja","Rahul","Meera","Vikram"},MOD(ROW()-2,8)+1)} -> Pooja | L30: {=INDEX({"UPI","Credit Card","Debit Card","Cash","Net Banking"},MOD(ROW()-2,5)+1)} -> Cash | M30: {=INDEX({"Retail","Corporate","Education","Small Business"},MOD(ROW()-2,4)+1)} -> Retail
A31: ="CUST"&TEXT(ROW()-1,"0000") -> CUST0030 | B31: {=INDEX({"Aarav","Vivaan","Aditya","Arjun","Kabir","Rohan","Ananya","Diya","Ishita","Meera","Riya","Pooja","Neha","Kavya","Aisha","Priya","Rahul","Karan","Vikram","Sahil"},MOD(ROW()-2,20)+1)&" "&INDEX({"Shah","Patel","Mehta","Desai","Joshi","Gupta","Verma","Sharma","Trivedi","Rana","Mishra","Kapoor","Iyer","Nair","Singh"},MOD(INT((ROW()-2)/20),15)+1)} -> Meera Patel | C31: {=INDEX({"North","South","East","West","Central"},MOD(ROW()-2,5)+1)} -> Central | D31: {=INDEX({"Electronics","Clothing","Furniture","Books","Office Supplies"},MOD(ROW()-2,5)+1)} -> Office Supplies | E31: =ROUND(500+MOD((ROW()-2)*137,44500),2) -> 4473 | F31: =MOD((ROW()-2)*7,11)+1 -> 6 | G31: =CHOOSE(MOD(ROW()-2,8)+1,0,0.02,0.05,0.08,0.1,0.12,0.15,0.2) -> 0.12 | H31: =DATE(2025,1,1)+MOD(ROW()-2,365) -> 45687 | I31: =ROUND(E31*F31*(1-G31),2) -> 23617.44 | J31: =ROUND(I31*(0.08+MOD(ROW()-2,12)*0.02),2) -> 4251.14 | K31: {=INDEX({"Amit","Neha","Riya","Karan","Pooja","Rahul","Meera","Vikram"},MOD(ROW()-2,8)+1)} -> Rahul | L31: {=INDEX({"UPI","Credit Card","Debit Card","Cash","Net Banking"},MOD(ROW()-2,5)+1)} -> Net Banking | M31: {=INDEX({"Retail","Corporate","Education","Small Business"},MOD(ROW()-2,4)+1)} -> Corporate
A32: ="CUST"&TEXT(ROW()-1,"0000") -> CUST0031 | B32: {=INDEX({"Aarav","Vivaan","Aditya","Arjun","Kabir","Rohan","Ananya","Diya","Ishita","Meera","Riya","Pooja","Neha","Kavya","Aisha","Priya","Rahul","Karan","Vikram","Sahil"},MOD(ROW()-2,20)+1)&" "&INDEX({"Shah","Patel","Mehta","Desai","Joshi","Gupta","Verma","Sharma","Trivedi","Rana","Mishra","Kapoor","Iyer","Nair","Singh"},MOD(INT((ROW()-2)/20),15)+1)} -> Riya Patel | C32: {=INDEX({"North","South","East","West","Central"},MOD(ROW()-2,5)+1)} -> North | D32: {=INDEX({"Electronics","Clothing","Furniture","Books","Office Supplies"},MOD(ROW()-2,5)+1)} -> Electronics | E32: =ROUND(500+MOD((ROW()-2)*137,44500),2) -> 4610 | F32: =MOD((ROW()-2)*7,11)+1 -> 2 | G32: =CHOOSE(MOD(ROW()-2,8)+1,0,0.02,0.05,0.08,0.1,0.12,0.15,0.2) -> 0.15 | H32: =DATE(2025,1,1)+MOD(ROW()-2,365) -> 45688 | I32: =ROUND(E32*F32*(1-G32),2) -> 7837 | J32: =ROUND(I32*(0.08+MOD(ROW()-2,12)*0.02),2) -> 1567.4 | K32: {=INDEX({"Amit","Neha","Riya","Karan","Pooja","Rahul","Meera","Vikram"},MOD(ROW()-2,8)+1)} -> Meera | L32: {=INDEX({"UPI","Credit Card","Debit Card","Cash","Net Banking"},MOD(ROW()-2,5)+1)} -> UPI | M32: {=INDEX({"Retail","Corporate","Education","Small Business"},MOD(ROW()-2,4)+1)} -> Education
A33: ="CUST"&TEXT(ROW()-1,"0000") -> CUST0032 | B33: {=INDEX({"Aarav","Vivaan","Aditya","Arjun","Kabir","Rohan","Ananya","Diya","Ishita","Meera","Riya","Pooja","Neha","Kavya","Aisha","Priya","Rahul","Karan","Vikram","Sahil"},MOD(ROW()-2,20)+1)&" "&INDEX({"Shah","Patel","Mehta","Desai","Joshi","Gupta","Verma","Sharma","Trivedi","Rana","Mishra","Kapoor","Iyer","Nair","Singh"},MOD(INT((ROW()-2)/20),15)+1)} -> Pooja Patel | C33: {=INDEX({"North","South","East","West","Central"},MOD(ROW()-2,5)+1)} -> South | D33: {=INDEX({"Electronics","Clothing","Furniture","Books","Office Supplies"},MOD(ROW()-2,5)+1)} -> Clothing | E33: =ROUND(500+MOD((ROW()-2)*137,44500),2) -> 4747 | F33: =MOD((ROW()-2)*7,11)+1 -> 9 | G33: =CHOOSE(MOD(ROW()-2,8)+1,0,0.02,0.05,0.08,0.1,0.12,0.15,0.2) -> 0.2 | H33: =DATE(2025,1,1)+MOD(ROW()-2,365) -> 45689 | I33: =ROUND(E33*F33*(1-G33),2) -> 34178.4 | J33: =ROUND(I33*(0.08+MOD(ROW()-2,12)*0.02),2) -> 7519.25 | K33: {=INDEX({"Amit","Neha","Riya","Karan","Pooja","Rahul","Meera","Vikram"},MOD(ROW()-2,8)+1)} -> Vikram | L33: {=INDEX({"UPI","Credit Card","Debit Card","Cash","Net Banking"},MOD(ROW()-2,5)+1)} -> Credit Card | M33: {=INDEX({"Retail","Corporate","Education","Small Business"},MOD(ROW()-2,4)+1)} -> Small Business
A34: ="CUST"&TEXT(ROW()-1,"0000") -> CUST0033 | B34: {=INDEX({"Aarav","Vivaan","Aditya","Arjun","Kabir","Rohan","Ananya","Diya","Ishita","Meera","Riya","Pooja","Neha","Kavya","Aisha","Priya","Rahul","Karan","Vikram","Sahil"},MOD(ROW()-2,20)+1)&" "&INDEX({"Shah","Patel","Mehta","Desai","Joshi","Gupta","Verma","Sharma","Trivedi","Rana","Mishra","Kapoor","Iyer","Nair","Singh"},MOD(INT((ROW()-2)/20),15)+1)} -> Neha Patel | C34: {=INDEX({"North","South","East","West","Central"},MOD(ROW()-2,5)+1)} -> East | D34: {=INDEX({"Electronics","Clothing","Furniture","Books","Office Supplies"},MOD(ROW()-2,5)+1)} -> Furniture | E34: =ROUND(500+MOD((ROW()-2)*137,44500),2) -> 4884 | F34: =MOD((ROW()-2)*7,11)+1 -> 5 | G34: =CHOOSE(MOD(ROW()-2,8)+1,0,0.02,0.05,0.08,0.1,0.12,0.15,0.2) -> 0 | H34: =DATE(2025,1,1)+MOD(ROW()-2,365) -> 45690 | I34: =ROUND(E34*F34*(1-G34),2) -> 24420 | J34: =ROUND(I34*(0.08+MOD(ROW()-2,12)*0.02),2) -> 5860.8 | K34: {=INDEX({"Amit","Neha","Riya","Karan","Pooja","Rahul","Meera","Vikram"},MOD(ROW()-2,8)+1)} -> Amit | L34: {=INDEX({"UPI","Credit Card","Debit Card","Cash","Net Banking"},MOD(ROW()-2,5)+1)} -> Debit Card | M34: {=INDEX({"Retail","Corporate","Education","Small Business"},MOD(ROW()-2,4)+1)} -> Retail
A35: ="CUST"&TEXT(ROW()-1,"0000") -> CUST0034 | B35: {=INDEX({"Aarav","Vivaan","Aditya","Arjun","Kabir","Rohan","Ananya","Diya","Ishita","Meera","Riya","Pooja","Neha","Kavya","Aisha","Priya","Rahul","Karan","Vikram","Sahil"},MOD(ROW()-2,20)+1)&" "&INDEX({"Shah","Patel","Mehta","Desai","Joshi","Gupta","Verma","Sharma","Trivedi","Rana","Mishra","Kapoor","Iyer","Nair","Singh"},MOD(INT((ROW()-2)/20),15)+1)} -> Kavya Patel | C35: {=INDEX({"North","South","East","West","Central"},MOD(ROW()-2,5)+1)} -> West | D35: {=INDEX({"Electronics","Clothing","Furniture","Books","Office Supplies"},MOD(ROW()-2,5)+1)} -> Books | E35: =ROUND(500+MOD((ROW()-2)*137,44500),2) -> 5021 | F35: =MOD((ROW()-2)*7,11)+1 -> 1 | G35: =CHOOSE(MOD(ROW()-2,8)+1,0,0.02,0.05,0.08,0.1,0.12,0.15,0.2) -> 0.02 | H35: =DATE(2025,1,1)+MOD(ROW()-2,365) -> 45691 | I35: =ROUND(E35*F35*(1-G35),2) -> 4920.58 | J35: =ROUND(I35*(0.08+MOD(ROW()-2,12)*0.02),2) -> 1279.35 | K35: {=INDEX({"Amit","Neha","Riya","Karan","Pooja","Rahul","Meera","Vikram"},MOD(ROW()-2,8)+1)} -> Neha | L35: {=INDEX({"UPI","Credit Card","Debit Card","Cash","Net Banking"},MOD(ROW()-2,5)+1)} -> Cash | M35: {=INDEX({"Retail","Corporate","Education","Small Business"},MOD(ROW()-2,4)+1)} -> Corporate
A36: ="CUST"&TEXT(ROW()-1,"0000") -> CUST0035 | B36: {=INDEX({"Aarav","Vivaan","Aditya","Arjun","Kabir","Rohan","Ananya","Diya","Ishita","Meera","Riya","Pooja","Neha","Kavya","Aisha","Priya","Rahul","Karan","Vikram","Sahil"},MOD(ROW()-2,20)+1)&" "&INDEX({"Shah","Patel","Mehta","Desai","Joshi","Gupta","Verma","Sharma","Trivedi","Rana","Mishra","Kapoor","Iyer","Nair","Singh"},MOD(INT((ROW()-2)/20),15)+1)} -> Aisha Patel | C36: {=INDEX({"North","South","East","West","Central"},MOD(ROW()-2,5)+1)} -> Central | D36: {=INDEX({"Electronics","Clothing","Furniture","Books","Office Supplies"},MOD(ROW()-2,5)+1)} -> Office Supplies | E36: =ROUND(500+MOD((ROW()-2)*137,44500),2) -> 5158 | F36: =MOD((ROW()-2)*7,11)+1 -> 8 | G36: =CHOOSE(MOD(ROW()-2,8)+1,0,0.02,0.05,0.08,0.1,0.12,0.15,0.2) -> 0.05 | H36: =DATE(2025,1,1)+MOD(ROW()-2,365) -> 45692 | I36: =ROUND(E36*F36*(1-G36),2) -> 39200.8 | J36: =ROUND(I36*(0.08+MOD(ROW()-2,12)*0.02),2) -> 10976.22 | K36: {=INDEX({"Amit","Neha","Riya","Karan","Pooja","Rahul","Meera","Vikram"},MOD(ROW()-2,8)+1)} -> Riya | L36: {=INDEX({"UPI","Credit Card","Debit Card","Cash","Net Banking"},MOD(ROW()-2,5)+1)} -> Net Banking | M36: {=INDEX({"Retail","Corporate","Education","Small Business"},MOD(ROW()-2,4)+1)} -> Education
A37: ="CUST"&TEXT(ROW()-1,"0000") -> CUST0036 | B37: {=INDEX({"Aarav","Vivaan","Aditya","Arjun","Kabir","Rohan","Ananya","Diya","Ishita","Meera","Riya","Pooja","Neha","Kavya","Aisha","Priya","Rahul","Karan","Vikram","Sahil"},MOD(ROW()-2,20)+1)&" "&INDEX({"Shah","Patel","Mehta","Desai","Joshi","Gupta","Verma","Sharma","Trivedi","Rana","Mishra","Kapoor","Iyer","Nair","Singh"},MOD(INT((ROW()-2)/20),15)+1)} -> Priya Patel | C37: {=INDEX({"North","South","East","West","Central"},MOD(ROW()-2,5)+1)} -> North | D37: {=INDEX({"Electronics","Clothing","Furniture","Books","Office Supplies"},MOD(ROW()-2,5)+1)} -> Electronics | E37: =ROUND(500+MOD((ROW()-2)*137,44500),2) -> 5295 | F37: =MOD((ROW()-2)*7,11)+1 -> 4 | G37: =CHOOSE(MOD(ROW()-2,8)+1,0,0.02,0.05,0.08,0.1,0.12,0.15,0.2) -> 0.08 | H37: =DATE(2025,1,1)+MOD(ROW()-2,365) -> 45693 | I37: =ROUND(E37*F37*(1-G37),2) -> 19485.6 | J37: =ROUND(I37*(0.08+MOD(ROW()-2,12)*0.02),2) -> 5845.68 | K37: {=INDEX({"Amit","Neha","Riya","Karan","Pooja","Rahul","Meera","Vikram"},MOD(ROW()-2,8)+1)} -> Karan | L37: {=INDEX({"UPI","Credit Card","Debit Card","Cash","Net Banking"},MOD(ROW()-2,5)+1)} -> UPI | M37: {=INDEX({"Retail","Corporate","Education","Small Business"},MOD(ROW()-2,4)+1)} -> Small Business
... A51: ="CUST"&TEXT(ROW()-1,"0000") -> CUST0050 | B51: {=INDEX({"Aarav","Vivaan","Aditya","Arjun","Kabir","Rohan","Ananya","Diya","Ishita","Meera","Riya","Pooja","Neha","Kavya","Aisha","Priya","Rahul","Karan","Vikram","Sahil"},MOD(ROW()-2,20)+1)&" "&INDEX({"Shah","Patel","Mehta","Desai","Joshi","Gupta","Verma","Sharma","Trivedi","Rana","Mishra","Kapoor","Iyer","Nair","Singh"},MOD(INT((ROW()-2)/20),15)+1)} -> Meera Mehta | C51: {=INDEX({"North","South","East","West","Central"},MOD(ROW()-2,5)+1)} -> Central | D51: {=INDEX({"Electronics","Clothing","Furniture","Books","Office Supplies"},MOD(ROW()-2,5)+1)} -> Office Supplies | E51: =ROUND(500+MOD((ROW()-2)*137,44500),2) -> 7213 | F51: =MOD((ROW()-2)*7,11)+1 -> 3 | G51: =CHOOSE(MOD(ROW()-2,8)+1,0,0.02,0.05,0.08,0.1,0.12,0.15,0.2) -> 0.02 | H51: =DATE(2025,1,1)+MOD(ROW()-2,365) -> 45707 | I51: =ROUND(E51*F51*(1-G51),2) -> 21206.22 | J51: =ROUND(I51*(0.08+MOD(ROW()-2,12)*0.02),2) -> 2120.62 | K51: {=INDEX({"Amit","Neha","Riya","Karan","Pooja","Rahul","Meera","Vikram"},MOD(ROW()-2,8)+1)} -> Neha | L51: {=INDEX({"UPI","Credit Card","Debit Card","Cash","Net Banking"},MOD(ROW()-2,5)+1)} -> Net Banking | M51: {=INDEX({"Retail","Corporate","Education","Small Business"},MOD(ROW()-2,4)+1)} -> Corporate
A52: ="CUST"&TEXT(ROW()-1,"0000") -> CUST0051 | B52: Rahul Desai | C52: {=INDEX({"North","South","East","West","Central"},MOD(ROW()-2,5)+1)} -> North | D52: {=INDEX({"Electronics","Clothing","Furniture","Books","Office Supplies"},MOD(ROW()-2,5)+1)} -> Electronics | E52: =ROUND(500+MOD((ROW()-2)*137,44500),2) -> 7350 | F52: =MOD((ROW()-2)*7,11)+1 -> 10 | G52: =CHOOSE(MOD(ROW()-2,8)+1,0,0.02,0.05,0.08,0.1,0.12,0.15,0.2) -> 0.05 | H52: =DATE(2025,1,1)+MOD(ROW()-2,365) -> 45708 | I52: =ROUND(E52*F52*(1-G52),2) -> 69825 | J52: =ROUND(I52*(0.08+MOD(ROW()-2,12)*0.02),2) -> 8379 | K52: {=INDEX({"Amit","Neha","Riya","Karan","Pooja","Rahul","Meera","Vikram"},MOD(ROW()-2,8)+1)} -> Riya | L52: {=INDEX({"UPI","Credit Card","Debit Card","Cash","Net Banking"},MOD(ROW()-2,5)+1)} -> UPI | M52: {=INDEX({"Retail","Corporate","Education","Small Business"},MOD(ROW()-2,4)+1)} -> Education
A53: ="CUST"&TEXT(ROW()-1,"0000") -> CUST0052 | B53: {=INDEX({"Aarav","Vivaan","Aditya","Arjun","Kabir","Rohan","Ananya","Diya","Ishita","Meera","Riya","Pooja","Neha","Kavya","Aisha","Priya","Rahul","Karan","Vikram","Sahil"},MOD(ROW()-2,20)+1)&" "&INDEX({"Shah","Patel","Mehta","Desai","Joshi","Gupta","Verma","Sharma","Trivedi","Rana","Mishra","Kapoor","Iyer","Nair","Singh"},MOD(INT((ROW()-2)/20),15)+1)} -> Pooja Mehta | C53: {=INDEX({"North","South","East","West","Central"},MOD(ROW()-2,5)+1)} -> South | D53: {=INDEX({"Electronics","Clothing","Furniture","Books","Office Supplies"},MOD(ROW()-2,5)+1)} -> Clothing | E53: =ROUND(500+MOD((ROW()-2)*137,44500),2) -> 7487 | F53: =MOD((ROW()-2)*7,11)+1 -> 6 | G53: =CHOOSE(MOD(ROW()-2,8)+1,0,0.02,0.05,0.08,0.1,0.12,0.15,0.2) -> 0.08 | H53: =DATE(2025,1,1)+MOD(ROW()-2,365) -> 45709 | I53: =ROUND(E53*F53*(1-G53),2) -> 41328.24 | J53: =ROUND(I53*(0.08+MOD(ROW()-2,12)*0.02),2) -> 5785.95 | K53: {=INDEX({"Amit","Neha","Riya","Karan","Pooja","Rahul","Meera","Vikram"},MOD(ROW()-2,8)+1)} -> Karan | L53: {=INDEX({"UPI","Credit Card","Debit Card","Cash","Net Banking"},MOD(ROW()-2,5)+1)} -> Credit Card | M53: {=INDEX({"Retail","Corporate","Education","Small Business"},MOD(ROW()-2,4)+1)} -> Small Business
A54: ="CUST"&TEXT(ROW()-1,"0000") -> CUST0053 | B54: {=INDEX({"Aarav","Vivaan","Aditya","Arjun","Kabir","Rohan","Ananya","Diya","Ishita","Meera","Riya","Pooja","Neha","Kavya","Aisha","Priya","Rahul","Karan","Vikram","Sahil"},MOD(ROW()-2,20)+1)&" "&INDEX({"Shah","Patel","Mehta","Desai","Joshi","Gupta","Verma","Sharma","Trivedi","Rana","Mishra","Kapoor","Iyer","Nair","Singh"},MOD(INT((ROW()-2)/20),15)+1)} -> Neha Mehta | C54: {=INDEX({"North","South","East","West","Central"},MOD(ROW()-2,5)+1)} -> East | D54: {=INDEX({"Electronics","Clothing","Furniture","Books","Office Supplies"},MOD(ROW()-2,5)+1)} -> Furniture | E54: =ROUND(500+MOD((ROW()-2)*137,44500),2) -> 7624 | F54: =MOD((ROW()-2)*7,11)+1 -> 2 | G54: =CHOOSE(MOD(ROW()-2,8)+1,0,0.02,0.05,0.08,0.1,0.12,0.15,0.2) -> 0.1 | H54: =DATE(2025,1,1)+MOD(ROW()-2,365) -> 45710 | I54: =ROUND(E54*F54*(1-G54),2) -> 13723.2 | J54: =ROUND(I54*(0.08+MOD(ROW()-2,12)*0.02),2) -> 2195.71 | K54: {=INDEX({"Amit","Neha","Riya","Karan","Pooja","Rahul","Meera","Vikram"},MOD(ROW()-2,8)+1)} -> Pooja | L54: {=INDEX({"UPI","Credit Card","Debit Card","Cash","Net Banking"},MOD(ROW()-2,5)+1)} -> Debit Card | M54: {=INDEX({"Retail","Corporate","Education","Small Business"},MOD(ROW()-2,4)+1)} -> Retail
...

Sheet Dashboard
A1: Sales Dahsboard
D3: Total Sales | I3: Total Profit | N3: Total Quantity | T3: Total Orders
D4: =SUM(DataSet!I2:I229) -> 19453783 | I4: =SUM(DataSet!J2:J229) -> 3655425.9 | N4: =SUM(DataSet!F2:F229) -> 1365 | T4: =COUNTA(DataSet!A2:A229) -> 228

Sheet Main Task
A1: Task 4.1: Use VLOOKUP to retrieve the Region Manager for each customer based on their Region. | K1: Task 5.1: Create a column chart showing Total Sales by Region.
S2: Task 7: Documentation
A3: Customer_ID | B3: Region | C3: Region_Manager | E3: Region | F3: Region_Manager | G3: Region_Target | M3: Region | N3: Total Sales
A4: =DataSet!A2 -> CUST0001 | B4: =DataSet!C2 -> North | C4: =IFERROR(VLOOKUP(B4,$E$4:$F$8,2,FALSE),"Not Found") -> Amit Shah | E4: North | F4: Amit Shah | G4: 500000 | M4: North | N4: =SUMIF(DataSet!$C$2:$C$328,M4,DataSet!$I$2:$I$230) -> 3866226.5 | S4: Workbook Sheets
A5: =DataSet!A3 -> CUST0002 | B5: =DataSet!C3 -> South | C5: =IFERROR(VLOOKUP(B5,$E$4:$F$8,2,FALSE),"Not Found") -> Neha Patel | E5: South | F5: Neha Patel | G5: 450000 | M5: South | N5: =SUMIF(DataSet!$C$2:$C$328,M5,DataSet!$I$2:$I$230) -> 3919562.1 | S5: Dataset – Contains the cleaned sales dataset
A6: =DataSet!A4 -> CUST0003 | B6: =DataSet!C4 -> East | C6: =IFERROR(VLOOKUP(B6,$E$4:$F$8,2,FALSE),"Not Found") -> Riya Mehta | E6: East | F6: Riya Mehta | G6: 400000 | M6: East | N6: =SUMIF(DataSet!$C$2:$C$328,M6,DataSet!$I$2:$I$230) -> 3891741.7 | S6: Pivot Tables – Contains Pivot Tables, Slicer and Timeline
A7: =DataSet!A5 -> CUST0004 | B7: =DataSet!C5 -> West | C7: =IFERROR(VLOOKUP(B7,$E$4:$F$8,2,FALSE),"Not Found") -> Karan Desai | E7: West | F7: Karan Desai | G7: 550000 | M7: West | N7: =SUMIF(DataSet!$C$2:$C$328,M7,DataSet!$I$2:$I$230) -> 4097279.9 | S7: Main Task – Contains formulas, calculations and charts
A8: =DataSet!A6 -> CUST0005 | B8: =DataSet!C6 -> Central | C8: =IFERROR(VLOOKUP(B8,$E$4:$F$8,2,FALSE),"Not Found") -> Pooja Joshi | E8: Central | F8: Pooja Joshi | G8: 480000 | M8: Central | N8: =SUMIF(DataSet!$C$2:$C$328,M8,DataSet!$I$2:$I$230) -> 3678973.1 | S8: Dashboard – Contains KPIs and visual charts
A9: =DataSet!A7 -> CUST0006 | B9: =DataSet!C7 -> North | C9: =IFERROR(VLOOKUP(B9,$E$4:$F$8,2,FALSE),"Not Found") -> Amit Shah | S9: Key Excel Functions Used
A10: =DataSet!A8 -> CUST0007 | B10: =DataSet!C8 -> South | C10: =IFERROR(VLOOKUP(B10,$E$4:$F$8,2,FALSE),"Not Found") -> Neha Patel | S10: SUM, SUMIF, COUNTA, IF, Nested IF, VLOOKUP, INDEX-MATCH
A11: =DataSet!A9 -> CUST0008 | B11: =DataSet!C9 -> East | C11: =IFERROR(VLOOKUP(B11,$E$4:$F$8,2,FALSE),"Not Found") -> Riya Mehta | S11: Dashboard Components
A12: =DataSet!A10 -> CUST0009 | B12: =DataSet!C10 -> West | C12: =IFERROR(VLOOKUP(B12,$E$4:$F$8,2,FALSE),"Not Found") -> Karan Desai | S12: KPI Cards, Column Charts, Bar Chart, Slicer and Timeline
A13: =DataSet!A11 -> CUST0010 | B13: =DataSet!C11 -> Central | C13: =IFERROR(VLOOKUP(B13,$E$4:$F$8,2,FALSE),"Not Found") -> Pooja Joshi | S13: Instructions
A14: =DataSet!A12 -> CUST0011 | B14: =DataSet!C12 -> North | C14: =IFERROR(VLOOKUP(B14,$E$4:$F$8,2,FALSE),"Not Found") -> Amit Shah | S14: Use the Slicer and Timeline on the Pivot Tables sheet to filter Pivot Table data.
A15: =DataSet!A13 -> CUST0012 | B15: =DataSet!C13 -> South | C15: =IFERROR(VLOOKUP(B15,$E$4:$F$8,2,FALSE),"Not Found") -> Neha Patel | S15: The Dataset contains 228 sales records and has been cleaned and formatted for analysis.
A16: =DataSet!A14 -> CUST0013 | B16: =DataSet!C14 -> East | C16: =IFERROR(VLOOKUP(B16,$E$4:$F$8,2,FALSE),"Not Found") -> Riya Mehta | S16: Naming Convention
A17: =DataSet!A15 -> CUST0014 | B17: =DataSet!C15 -> West | C17: =IFERROR(VLOOKUP(B17,$E$4:$F$8,2,FALSE),"Not Found") -> Karan Desai | S17: Sheets and charts are given clear and descriptive names for easy identification.
A18: =DataSet!A16 -> CUST0015 | B18: =DataSet!C16 -> Central | C18: =IFERROR(VLOOKUP(B18,$E$4:$F$8,2,FALSE),"Not Found") -> Pooja Joshi
A19: =DataSet!A17 -> CUST0016 | B19: =DataSet!C17 -> North | C19: =IFERROR(VLOOKUP(B19,$E$4:$F$8,2,FALSE),"Not Found") -> Amit Shah
A20: =DataSet!A18 -> CUST0017 | B20: =DataSet!C18 -> South | C20: =IFERROR(VLOOKUP(B20,$E$4:$F$8,2,FALSE),"Not Found") -> Neha Patel
A21: =DataSet!A19 -> CUST0018 | B21: =DataSet!C19 -> East | C21: =IFERROR(VLOOKUP(B21,$E$4:$F$8,2,FALSE),"Not Found") -> Riya Mehta
A22: =DataSet!A20 -> CUST0019 | B22: =DataSet!C20 -> West | C22: =IFERROR(VLOOKUP(B22,$E$4:$F$8,2,FALSE),"Not Found") -> Karan Desai
A23: =DataSet!A21 -> CUST0020 | B23: =DataSet!C21 -> Central | C23: =IFERROR(VLOOKUP(B23,$E$4:$F$8,2,FALSE),"Not Found") -> Pooja Joshi
A24: =DataSet!A22 -> CUST0021 | B24: =DataSet!C22 -> North | C24: =IFERROR(VLOOKUP(B24,$E$4:$F$8,2,FALSE),"Not Found") -> Amit Shah
A25: =DataSet!A23 -> CUST0022 | B25: =DataSet!C23 -> South | C25: =IFERROR(VLOOKUP(B25,$E$4:$F$8,2,FALSE),"Not Found") -> Neha Patel
A26: =DataSet!A24 -> CUST0023 | B26: =DataSet!C24 -> East | C26: =IFERROR(VLOOKUP(B26,$E$4:$F$8,2,FALSE),"Not Found") -> Riya Mehta
A27: =DataSet!A25 -> CUST0024 | B27: =DataSet!C25 -> West | C27: =IFERROR(VLOOKUP(B27,$E$4:$F$8,2,FALSE),"Not Found") -> Karan Desai | J27: Task 5.2: Apply conditional formatting to highlight High Value orders.
A28: =DataSet!A26 -> CUST0025 | B28: =DataSet!C26 -> Central | C28: =IFERROR(VLOOKUP(B28,$E$4:$F$8,2,FALSE),"Not Found") -> Pooja Joshi
A29: =DataSet!A27 -> CUST0026 | B29: =DataSet!C27 -> North | C29: =IFERROR(VLOOKUP(B29,$E$4:$F$8,2,FALSE),"Not Found") -> Amit Shah | J29: Customer_ID | K29: Sales | L29: Order_Type
A30: =DataSet!A28 -> CUST0027 | B30: =DataSet!C28 -> South | C30: =IFERROR(VLOOKUP(B30,$E$4:$F$8,2,FALSE),"Not Found") -> Neha Patel | J30: =DataSet!A2 -> CUST0001 | K30: =DataSet!I2 -> 500 | L30: =IF(K30>=25000,"High Value","Regular") -> Regular
A31: =DataSet!A29 -> CUST0028 | B31: =DataSet!C29 -> East | C31: =IFERROR(VLOOKUP(B31,$E$4:$F$8,2,FALSE),"Not Found") -> Riya Mehta | J31: =DataSet!A3 -> CUST0002 | K31: =DataSet!I3 -> 4994.08 | L31: =IF(K31>=25000,"High Value","Regular") -> Regular
A32: =DataSet!A30 -> CUST0029 | B32: =DataSet!C30 -> West | C32: =IFERROR(VLOOKUP(B32,$E$4:$F$8,2,FALSE),"Not Found") -> Karan Desai | J32: =DataSet!A4 -> CUST0003 | K32: =DataSet!I4 -> 2941.2 | L32: =IF(K32>=25000,"High Value","Regular") -> Regular
A33: =DataSet!A31 -> CUST0030 | B33: =DataSet!C31 -> Central | C33: =IFERROR(VLOOKUP(B33,$E$4:$F$8,2,FALSE),"Not Found") -> Pooja Joshi | J33: =DataSet!A5 -> CUST0004 | K33: =DataSet!I5 -> 9219.32 | L33: =IF(K33>=25000,"High Value","Regular") -> Regular
A34: =DataSet!A32 -> CUST0031 | B34: =DataSet!C32 -> North | C34: =IFERROR(VLOOKUP(B34,$E$4:$F$8,2,FALSE),"Not Found") -> Amit Shah | J34: =DataSet!A6 -> CUST0005 | K34: =DataSet!I6 -> 6602.4 | L34: =IF(K34>=25000,"High Value","Regular") -> Regular
A35: =DataSet!A33 -> CUST0032 | B35: =DataSet!C33 -> South | C35: =IFERROR(VLOOKUP(B35,$E$4:$F$8,2,FALSE),"Not Found") -> Neha Patel | J35: =DataSet!A7 -> CUST0006 | K35: =DataSet!I7 -> 3128.4 | L35: =IF(K35>=25000,"High Value","Regular") -> Regular
A36: =DataSet!A34 -> CUST0033 | B36: =DataSet!C34 -> East | C36: =IFERROR(VLOOKUP(B36,$E$4:$F$8,2,FALSE),"Not Found") -> Riya Mehta | J36: =DataSet!A8 -> CUST0007 | K36: =DataSet!I8 -> 11237 | L36: =IF(K36>=25000,"High Value","Regular") -> Regular
A37: =DataSet!A35 -> CUST0034 | B37: =DataSet!C35 -> West | C37: =IFERROR(VLOOKUP(B37,$E$4:$F$8,2,FALSE),"Not Found") -> Karan Desai | J37: =DataSet!A9 -> CUST0008 | K37: =DataSet!I9 -> 7003.2 | L37: =IF(K37>=25000,"High Value","Regular") -> Regular
A38: =DataSet!A36 -> CUST0035 | B38: =DataSet!C36 -> Central | C38: =IFERROR(VLOOKUP(B38,$E$4:$F$8,2,FALSE),"Not Found") -> Pooja Joshi | J38: =DataSet!A10 -> CUST0009 | K38: =DataSet!I10 -> 3192 | L38: =IF(K38>=25000,"High Value","Regular") -> Regular
A39: =DataSet!A37 -> CUST0036 | B39: =DataSet!C37 -> North | C39: =IFERROR(VLOOKUP(B39,$E$4:$F$8,2,FALSE),"Not Found") -> Amit Shah | J39: =DataSet!A11 -> CUST0010 | K39: =DataSet!I11 -> 15285.06 | L39: =IF(K39>=25000,"High Value","Regular") -> Regular
A40: =DataSet!A38 -> CUST0037 | B40: =DataSet!C38 -> South | C40: =IFERROR(VLOOKUP(B40,$E$4:$F$8,2,FALSE),"Not Found") -> Neha Patel | J40: =DataSet!A12 -> CUST0011 | K40: =DataSet!I12 -> 8882.5 | L40: =IF(K40>=25000,"High Value","Regular") -> Regular
...
